2019-06-23 19:17:19,030 [ERROR]  Unable to start server
Traceback (most recent call last):
  File "c:\users\feder\appdata\local\programs\python\python36\lib\site-packages\sanic\server.py", line 745, in serve
    http_server = loop.run_until_complete(server_coroutine)
  File "c:\users\feder\appdata\local\programs\python\python36\lib\asyncio\base_events.py", line 464, in run_until_complete
    raise RuntimeError('Event loop stopped before Future completed.')
RuntimeError: Event loop stopped before Future completed.
2019-06-24 21:05:06,455 [ERROR]  Exception occurred in one of response middleware handlers
Traceback (most recent call last):
  File "c:\users\feder\appdata\local\programs\python\python36\lib\site-packages\sanic\app.py", line 958, in handle_request
    request, response
  File "c:\users\feder\appdata\local\programs\python\python36\lib\site-packages\spf\framework.py", line 543, in _run_response_middleware
    _response = await _response
  File "c:\users\feder\appdata\local\programs\python\python36\lib\site-packages\sanic_cors\extension.py", line 266, in unapplied_cors_response_middleware
    set_cors_headers(req, resp, context, res_options)
  File "c:\users\feder\appdata\local\programs\python\python36\lib\site-packages\sanic_cors\core.py", line 248, in set_cors_headers
    if resp.headers is None:
AttributeError: 'list' object has no attribute 'headers'
2019-06-24 21:05:45,042 [ERROR]  Exception occurred in one of response middleware handlers
Traceback (most recent call last):
  File "c:\users\feder\appdata\local\programs\python\python36\lib\site-packages\sanic\app.py", line 958, in handle_request
    request, response
  File "c:\users\feder\appdata\local\programs\python\python36\lib\site-packages\spf\framework.py", line 543, in _run_response_middleware
    _response = await _response
  File "c:\users\feder\appdata\local\programs\python\python36\lib\site-packages\sanic_cors\extension.py", line 266, in unapplied_cors_response_middleware
    set_cors_headers(req, resp, context, res_options)
  File "c:\users\feder\appdata\local\programs\python\python36\lib\site-packages\sanic_cors\core.py", line 248, in set_cors_headers
    if resp.headers is None:
AttributeError: 'list' object has no attribute 'headers'
2019-06-24 21:05:53,604 [ERROR]  Exception occurred in one of response middleware handlers
Traceback (most recent call last):
  File "c:\users\feder\appdata\local\programs\python\python36\lib\site-packages\sanic\app.py", line 958, in handle_request
    request, response
  File "c:\users\feder\appdata\local\programs\python\python36\lib\site-packages\spf\framework.py", line 543, in _run_response_middleware
    _response = await _response
  File "c:\users\feder\appdata\local\programs\python\python36\lib\site-packages\sanic_cors\extension.py", line 266, in unapplied_cors_response_middleware
    set_cors_headers(req, resp, context, res_options)
  File "c:\users\feder\appdata\local\programs\python\python36\lib\site-packages\sanic_cors\core.py", line 248, in set_cors_headers
    if resp.headers is None:
AttributeError: 'list' object has no attribute 'headers'
2019-06-24 22:22:19,152 [ERROR]  Exception occurred in one of response middleware handlers
Traceback (most recent call last):
  File "c:\users\feder\appdata\local\programs\python\python36\lib\site-packages\sanic\app.py", line 958, in handle_request
    request, response
  File "c:\users\feder\appdata\local\programs\python\python36\lib\site-packages\spf\framework.py", line 543, in _run_response_middleware
    _response = await _response
  File "c:\users\feder\appdata\local\programs\python\python36\lib\site-packages\sanic_cors\extension.py", line 266, in unapplied_cors_response_middleware
    set_cors_headers(req, resp, context, res_options)
  File "c:\users\feder\appdata\local\programs\python\python36\lib\site-packages\sanic_cors\core.py", line 248, in set_cors_headers
    if resp.headers is None:
AttributeError: 'list' object has no attribute 'headers'
2019-06-24 22:23:59,947 [ERROR]  Exception occurred in one of response middleware handlers
Traceback (most recent call last):
  File "c:\users\feder\appdata\local\programs\python\python36\lib\site-packages\sanic\app.py", line 958, in handle_request
    request, response
  File "c:\users\feder\appdata\local\programs\python\python36\lib\site-packages\spf\framework.py", line 543, in _run_response_middleware
    _response = await _response
  File "c:\users\feder\appdata\local\programs\python\python36\lib\site-packages\sanic_cors\extension.py", line 266, in unapplied_cors_response_middleware
    set_cors_headers(req, resp, context, res_options)
  File "c:\users\feder\appdata\local\programs\python\python36\lib\site-packages\sanic_cors\core.py", line 248, in set_cors_headers
    if resp.headers is None:
AttributeError: 'list' object has no attribute 'headers'
2019-06-24 22:32:46,093 [ERROR]  Experienced exception while trying to serve
Traceback (most recent call last):
  File "c:\users\feder\appdata\local\programs\python\python36\lib\site-packages\sanic\app.py", line 1096, in run
    serve(**server_settings)
  File "c:\users\feder\appdata\local\programs\python\python36\lib\site-packages\sanic\server.py", line 770, in serve
    loop.run_forever()
  File "c:\users\feder\appdata\local\programs\python\python36\lib\asyncio\base_events.py", line 421, in run_forever
    self._run_once()
  File "c:\users\feder\appdata\local\programs\python\python36\lib\asyncio\base_events.py", line 1389, in _run_once
    event_list = self._selector.select(timeout)
  File "c:\users\feder\appdata\local\programs\python\python36\lib\selectors.py", line 323, in select
    r, w, _ = self._select(self._readers, self._writers, [], timeout)
  File "c:\users\feder\appdata\local\programs\python\python36\lib\selectors.py", line 314, in _select
    r, w, x = select.select(r, w, w, timeout)
  File "c:\users\feder\appdata\local\programs\python\python36\lib\site-packages\engineio\client.py", line 41, in signal_handler
    return original_signal_handler(sig, frame)
KeyboardInterrupt
2019-06-24 22:35:01,089 [ERROR]  Exception occurred in one of response middleware handlers
Traceback (most recent call last):
  File "c:\users\feder\appdata\local\programs\python\python36\lib\site-packages\sanic\app.py", line 958, in handle_request
    request, response
  File "c:\users\feder\appdata\local\programs\python\python36\lib\site-packages\spf\framework.py", line 543, in _run_response_middleware
    _response = await _response
  File "c:\users\feder\appdata\local\programs\python\python36\lib\site-packages\sanic_cors\extension.py", line 266, in unapplied_cors_response_middleware
    set_cors_headers(req, resp, context, res_options)
  File "c:\users\feder\appdata\local\programs\python\python36\lib\site-packages\sanic_cors\core.py", line 248, in set_cors_headers
    if resp.headers is None:
AttributeError: 'list' object has no attribute 'headers'
2019-06-24 22:35:13,210 [ERROR]  Exception occurred in one of response middleware handlers
Traceback (most recent call last):
  File "c:\users\feder\appdata\local\programs\python\python36\lib\site-packages\sanic\app.py", line 958, in handle_request
    request, response
  File "c:\users\feder\appdata\local\programs\python\python36\lib\site-packages\spf\framework.py", line 543, in _run_response_middleware
    _response = await _response
  File "c:\users\feder\appdata\local\programs\python\python36\lib\site-packages\sanic_cors\extension.py", line 266, in unapplied_cors_response_middleware
    set_cors_headers(req, resp, context, res_options)
  File "c:\users\feder\appdata\local\programs\python\python36\lib\site-packages\sanic_cors\core.py", line 248, in set_cors_headers
    if resp.headers is None:
AttributeError: 'list' object has no attribute 'headers'
2019-06-24 22:36:17,739 [ERROR]  Exception occurred in one of response middleware handlers
Traceback (most recent call last):
  File "c:\users\feder\appdata\local\programs\python\python36\lib\site-packages\sanic\app.py", line 958, in handle_request
    request, response
  File "c:\users\feder\appdata\local\programs\python\python36\lib\site-packages\spf\framework.py", line 543, in _run_response_middleware
    _response = await _response
  File "c:\users\feder\appdata\local\programs\python\python36\lib\site-packages\sanic_cors\extension.py", line 266, in unapplied_cors_response_middleware
    set_cors_headers(req, resp, context, res_options)
  File "c:\users\feder\appdata\local\programs\python\python36\lib\site-packages\sanic_cors\core.py", line 248, in set_cors_headers
    if resp.headers is None:
AttributeError: 'list' object has no attribute 'headers'
2019-06-24 22:36:27,050 [ERROR]  Exception occurred in one of response middleware handlers
Traceback (most recent call last):
  File "c:\users\feder\appdata\local\programs\python\python36\lib\site-packages\sanic\app.py", line 958, in handle_request
    request, response
  File "c:\users\feder\appdata\local\programs\python\python36\lib\site-packages\spf\framework.py", line 543, in _run_response_middleware
    _response = await _response
  File "c:\users\feder\appdata\local\programs\python\python36\lib\site-packages\sanic_cors\extension.py", line 266, in unapplied_cors_response_middleware
    set_cors_headers(req, resp, context, res_options)
  File "c:\users\feder\appdata\local\programs\python\python36\lib\site-packages\sanic_cors\core.py", line 248, in set_cors_headers
    if resp.headers is None:
AttributeError: 'list' object has no attribute 'headers'
2019-06-24 22:47:50,820 [ERROR]  Exception occurred in one of response middleware handlers
Traceback (most recent call last):
  File "c:\users\feder\appdata\local\programs\python\python36\lib\site-packages\sanic\app.py", line 958, in handle_request
    request, response
  File "c:\users\feder\appdata\local\programs\python\python36\lib\site-packages\spf\framework.py", line 543, in _run_response_middleware
    _response = await _response
  File "c:\users\feder\appdata\local\programs\python\python36\lib\site-packages\sanic_cors\extension.py", line 266, in unapplied_cors_response_middleware
    set_cors_headers(req, resp, context, res_options)
  File "c:\users\feder\appdata\local\programs\python\python36\lib\site-packages\sanic_cors\core.py", line 248, in set_cors_headers
    if resp.headers is None:
AttributeError: 'list' object has no attribute 'headers'
2019-06-24 22:48:00,294 [ERROR]  Exception occurred in one of response middleware handlers
Traceback (most recent call last):
  File "c:\users\feder\appdata\local\programs\python\python36\lib\site-packages\sanic\app.py", line 958, in handle_request
    request, response
  File "c:\users\feder\appdata\local\programs\python\python36\lib\site-packages\spf\framework.py", line 543, in _run_response_middleware
    _response = await _response
  File "c:\users\feder\appdata\local\programs\python\python36\lib\site-packages\sanic_cors\extension.py", line 266, in unapplied_cors_response_middleware
    set_cors_headers(req, resp, context, res_options)
  File "c:\users\feder\appdata\local\programs\python\python36\lib\site-packages\sanic_cors\core.py", line 248, in set_cors_headers
    if resp.headers is None:
AttributeError: 'list' object has no attribute 'headers'
2019-06-24 22:52:42,889 [ERROR]  Exception occurred in one of response middleware handlers
Traceback (most recent call last):
  File "c:\users\feder\appdata\local\programs\python\python36\lib\site-packages\sanic\app.py", line 958, in handle_request
    request, response
  File "c:\users\feder\appdata\local\programs\python\python36\lib\site-packages\spf\framework.py", line 543, in _run_response_middleware
    _response = await _response
  File "c:\users\feder\appdata\local\programs\python\python36\lib\site-packages\sanic_cors\extension.py", line 266, in unapplied_cors_response_middleware
    set_cors_headers(req, resp, context, res_options)
  File "c:\users\feder\appdata\local\programs\python\python36\lib\site-packages\sanic_cors\core.py", line 248, in set_cors_headers
    if resp.headers is None:
AttributeError: 'list' object has no attribute 'headers'
2019-06-24 22:52:52,362 [ERROR]  Exception occurred in one of response middleware handlers
Traceback (most recent call last):
  File "c:\users\feder\appdata\local\programs\python\python36\lib\site-packages\sanic\app.py", line 958, in handle_request
    request, response
  File "c:\users\feder\appdata\local\programs\python\python36\lib\site-packages\spf\framework.py", line 543, in _run_response_middleware
    _response = await _response
  File "c:\users\feder\appdata\local\programs\python\python36\lib\site-packages\sanic_cors\extension.py", line 266, in unapplied_cors_response_middleware
    set_cors_headers(req, resp, context, res_options)
  File "c:\users\feder\appdata\local\programs\python\python36\lib\site-packages\sanic_cors\core.py", line 248, in set_cors_headers
    if resp.headers is None:
AttributeError: 'list' object has no attribute 'headers'
2019-06-24 22:53:35,270 [ERROR]  Exception occurred in one of response middleware handlers
Traceback (most recent call last):
  File "c:\users\feder\appdata\local\programs\python\python36\lib\site-packages\sanic\app.py", line 958, in handle_request
    request, response
  File "c:\users\feder\appdata\local\programs\python\python36\lib\site-packages\spf\framework.py", line 543, in _run_response_middleware
    _response = await _response
  File "c:\users\feder\appdata\local\programs\python\python36\lib\site-packages\sanic_cors\extension.py", line 266, in unapplied_cors_response_middleware
    set_cors_headers(req, resp, context, res_options)
  File "c:\users\feder\appdata\local\programs\python\python36\lib\site-packages\sanic_cors\core.py", line 248, in set_cors_headers
    if resp.headers is None:
AttributeError: 'list' object has no attribute 'headers'
2019-06-24 22:54:40,657 [ERROR]  Exception occurred in one of response middleware handlers
Traceback (most recent call last):
  File "c:\users\feder\appdata\local\programs\python\python36\lib\site-packages\sanic\app.py", line 958, in handle_request
    request, response
  File "c:\users\feder\appdata\local\programs\python\python36\lib\site-packages\spf\framework.py", line 543, in _run_response_middleware
    _response = await _response
  File "c:\users\feder\appdata\local\programs\python\python36\lib\site-packages\sanic_cors\extension.py", line 266, in unapplied_cors_response_middleware
    set_cors_headers(req, resp, context, res_options)
  File "c:\users\feder\appdata\local\programs\python\python36\lib\site-packages\sanic_cors\core.py", line 248, in set_cors_headers
    if resp.headers is None:
AttributeError: 'list' object has no attribute 'headers'
2019-06-24 22:59:28,000 [ERROR]  Exception occurred in one of response middleware handlers
Traceback (most recent call last):
  File "c:\users\feder\appdata\local\programs\python\python36\lib\site-packages\sanic\app.py", line 958, in handle_request
    request, response
  File "c:\users\feder\appdata\local\programs\python\python36\lib\site-packages\spf\framework.py", line 543, in _run_response_middleware
    _response = await _response
  File "c:\users\feder\appdata\local\programs\python\python36\lib\site-packages\sanic_cors\extension.py", line 266, in unapplied_cors_response_middleware
    set_cors_headers(req, resp, context, res_options)
  File "c:\users\feder\appdata\local\programs\python\python36\lib\site-packages\sanic_cors\core.py", line 248, in set_cors_headers
    if resp.headers is None:
AttributeError: 'list' object has no attribute 'headers'
2019-06-24 23:00:22,481 [ERROR]  Exception occurred in one of response middleware handlers
Traceback (most recent call last):
  File "c:\users\feder\appdata\local\programs\python\python36\lib\site-packages\sanic\app.py", line 958, in handle_request
    request, response
  File "c:\users\feder\appdata\local\programs\python\python36\lib\site-packages\spf\framework.py", line 543, in _run_response_middleware
    _response = await _response
  File "c:\users\feder\appdata\local\programs\python\python36\lib\site-packages\sanic_cors\extension.py", line 266, in unapplied_cors_response_middleware
    set_cors_headers(req, resp, context, res_options)
  File "c:\users\feder\appdata\local\programs\python\python36\lib\site-packages\sanic_cors\core.py", line 248, in set_cors_headers
    if resp.headers is None:
AttributeError: 'list' object has no attribute 'headers'
2019-06-24 23:00:57,920 [ERROR]  Exception occurred in one of response middleware handlers
Traceback (most recent call last):
  File "c:\users\feder\appdata\local\programs\python\python36\lib\site-packages\sanic\app.py", line 958, in handle_request
    request, response
  File "c:\users\feder\appdata\local\programs\python\python36\lib\site-packages\spf\framework.py", line 543, in _run_response_middleware
    _response = await _response
  File "c:\users\feder\appdata\local\programs\python\python36\lib\site-packages\sanic_cors\extension.py", line 266, in unapplied_cors_response_middleware
    set_cors_headers(req, resp, context, res_options)
  File "c:\users\feder\appdata\local\programs\python\python36\lib\site-packages\sanic_cors\core.py", line 248, in set_cors_headers
    if resp.headers is None:
AttributeError: 'list' object has no attribute 'headers'
2019-06-24 23:01:47,521 [ERROR]  Exception occurred in one of response middleware handlers
Traceback (most recent call last):
  File "c:\users\feder\appdata\local\programs\python\python36\lib\site-packages\sanic\app.py", line 958, in handle_request
    request, response
  File "c:\users\feder\appdata\local\programs\python\python36\lib\site-packages\spf\framework.py", line 543, in _run_response_middleware
    _response = await _response
  File "c:\users\feder\appdata\local\programs\python\python36\lib\site-packages\sanic_cors\extension.py", line 266, in unapplied_cors_response_middleware
    set_cors_headers(req, resp, context, res_options)
  File "c:\users\feder\appdata\local\programs\python\python36\lib\site-packages\sanic_cors\core.py", line 248, in set_cors_headers
    if resp.headers is None:
AttributeError: 'list' object has no attribute 'headers'
2019-06-24 23:02:45,064 [ERROR]  Exception occurred in one of response middleware handlers
Traceback (most recent call last):
  File "c:\users\feder\appdata\local\programs\python\python36\lib\site-packages\sanic\app.py", line 958, in handle_request
    request, response
  File "c:\users\feder\appdata\local\programs\python\python36\lib\site-packages\spf\framework.py", line 543, in _run_response_middleware
    _response = await _response
  File "c:\users\feder\appdata\local\programs\python\python36\lib\site-packages\sanic_cors\extension.py", line 266, in unapplied_cors_response_middleware
    set_cors_headers(req, resp, context, res_options)
  File "c:\users\feder\appdata\local\programs\python\python36\lib\site-packages\sanic_cors\core.py", line 248, in set_cors_headers
    if resp.headers is None:
AttributeError: 'list' object has no attribute 'headers'
2019-06-24 23:03:22,101 [ERROR]  Exception occurred in one of response middleware handlers
Traceback (most recent call last):
  File "c:\users\feder\appdata\local\programs\python\python36\lib\site-packages\sanic\app.py", line 958, in handle_request
    request, response
  File "c:\users\feder\appdata\local\programs\python\python36\lib\site-packages\spf\framework.py", line 543, in _run_response_middleware
    _response = await _response
  File "c:\users\feder\appdata\local\programs\python\python36\lib\site-packages\sanic_cors\extension.py", line 266, in unapplied_cors_response_middleware
    set_cors_headers(req, resp, context, res_options)
  File "c:\users\feder\appdata\local\programs\python\python36\lib\site-packages\sanic_cors\core.py", line 248, in set_cors_headers
    if resp.headers is None:
AttributeError: 'list' object has no attribute 'headers'
2019-06-24 23:04:22,692 [ERROR]  Exception occurred while handling uri: unknown
NoneType: None
2019-06-24 23:07:17,920 [ERROR]  Exception occurred in one of response middleware handlers
Traceback (most recent call last):
  File "c:\users\feder\appdata\local\programs\python\python36\lib\site-packages\sanic\app.py", line 958, in handle_request
    request, response
  File "c:\users\feder\appdata\local\programs\python\python36\lib\site-packages\spf\framework.py", line 543, in _run_response_middleware
    _response = await _response
  File "c:\users\feder\appdata\local\programs\python\python36\lib\site-packages\sanic_cors\extension.py", line 266, in unapplied_cors_response_middleware
    set_cors_headers(req, resp, context, res_options)
  File "c:\users\feder\appdata\local\programs\python\python36\lib\site-packages\sanic_cors\core.py", line 248, in set_cors_headers
    if resp.headers is None:
AttributeError: 'list' object has no attribute 'headers'
2019-06-24 23:07:32,993 [ERROR]  Exception occurred in one of response middleware handlers
Traceback (most recent call last):
  File "c:\users\feder\appdata\local\programs\python\python36\lib\site-packages\sanic\app.py", line 958, in handle_request
    request, response
  File "c:\users\feder\appdata\local\programs\python\python36\lib\site-packages\spf\framework.py", line 543, in _run_response_middleware
    _response = await _response
  File "c:\users\feder\appdata\local\programs\python\python36\lib\site-packages\sanic_cors\extension.py", line 266, in unapplied_cors_response_middleware
    set_cors_headers(req, resp, context, res_options)
  File "c:\users\feder\appdata\local\programs\python\python36\lib\site-packages\sanic_cors\core.py", line 248, in set_cors_headers
    if resp.headers is None:
AttributeError: 'list' object has no attribute 'headers'
2019-06-24 23:08:02,783 [ERROR]  Exception occurred in one of response middleware handlers
Traceback (most recent call last):
  File "c:\users\feder\appdata\local\programs\python\python36\lib\site-packages\sanic\app.py", line 958, in handle_request
    request, response
  File "c:\users\feder\appdata\local\programs\python\python36\lib\site-packages\spf\framework.py", line 543, in _run_response_middleware
    _response = await _response
  File "c:\users\feder\appdata\local\programs\python\python36\lib\site-packages\sanic_cors\extension.py", line 266, in unapplied_cors_response_middleware
    set_cors_headers(req, resp, context, res_options)
  File "c:\users\feder\appdata\local\programs\python\python36\lib\site-packages\sanic_cors\core.py", line 248, in set_cors_headers
    if resp.headers is None:
AttributeError: 'list' object has no attribute 'headers'
2019-06-24 23:09:44,392 [ERROR]  Exception occurred in one of response middleware handlers
Traceback (most recent call last):
  File "c:\users\feder\appdata\local\programs\python\python36\lib\site-packages\sanic\app.py", line 958, in handle_request
    request, response
  File "c:\users\feder\appdata\local\programs\python\python36\lib\site-packages\spf\framework.py", line 543, in _run_response_middleware
    _response = await _response
  File "c:\users\feder\appdata\local\programs\python\python36\lib\site-packages\sanic_cors\extension.py", line 266, in unapplied_cors_response_middleware
    set_cors_headers(req, resp, context, res_options)
  File "c:\users\feder\appdata\local\programs\python\python36\lib\site-packages\sanic_cors\core.py", line 248, in set_cors_headers
    if resp.headers is None:
AttributeError: 'list' object has no attribute 'headers'
2019-06-24 23:11:57,346 [ERROR]  Exception occurred in one of response middleware handlers
Traceback (most recent call last):
  File "c:\users\feder\appdata\local\programs\python\python36\lib\site-packages\sanic\app.py", line 958, in handle_request
    request, response
  File "c:\users\feder\appdata\local\programs\python\python36\lib\site-packages\spf\framework.py", line 543, in _run_response_middleware
    _response = await _response
  File "c:\users\feder\appdata\local\programs\python\python36\lib\site-packages\sanic_cors\extension.py", line 266, in unapplied_cors_response_middleware
    set_cors_headers(req, resp, context, res_options)
  File "c:\users\feder\appdata\local\programs\python\python36\lib\site-packages\sanic_cors\core.py", line 248, in set_cors_headers
    if resp.headers is None:
AttributeError: 'list' object has no attribute 'headers'
2019-06-24 23:12:21,988 [ERROR]  Exception occurred in one of response middleware handlers
Traceback (most recent call last):
  File "c:\users\feder\appdata\local\programs\python\python36\lib\site-packages\sanic\app.py", line 958, in handle_request
    request, response
  File "c:\users\feder\appdata\local\programs\python\python36\lib\site-packages\spf\framework.py", line 543, in _run_response_middleware
    _response = await _response
  File "c:\users\feder\appdata\local\programs\python\python36\lib\site-packages\sanic_cors\extension.py", line 266, in unapplied_cors_response_middleware
    set_cors_headers(req, resp, context, res_options)
  File "c:\users\feder\appdata\local\programs\python\python36\lib\site-packages\sanic_cors\core.py", line 248, in set_cors_headers
    if resp.headers is None:
AttributeError: 'list' object has no attribute 'headers'
2019-06-24 23:14:57,124 [ERROR]  Exception occurred in one of response middleware handlers
Traceback (most recent call last):
  File "c:\users\feder\appdata\local\programs\python\python36\lib\site-packages\sanic\app.py", line 958, in handle_request
    request, response
  File "c:\users\feder\appdata\local\programs\python\python36\lib\site-packages\spf\framework.py", line 543, in _run_response_middleware
    _response = await _response
  File "c:\users\feder\appdata\local\programs\python\python36\lib\site-packages\sanic_cors\extension.py", line 266, in unapplied_cors_response_middleware
    set_cors_headers(req, resp, context, res_options)
  File "c:\users\feder\appdata\local\programs\python\python36\lib\site-packages\sanic_cors\core.py", line 248, in set_cors_headers
    if resp.headers is None:
AttributeError: 'list' object has no attribute 'headers'
2019-06-24 23:15:57,707 [ERROR]  Exception occurred while handling uri: unknown
NoneType: None
2019-06-24 23:18:20,531 [ERROR]  Exception occurred in one of response middleware handlers
Traceback (most recent call last):
  File "c:\users\feder\appdata\local\programs\python\python36\lib\site-packages\sanic\app.py", line 958, in handle_request
    request, response
  File "c:\users\feder\appdata\local\programs\python\python36\lib\site-packages\spf\framework.py", line 543, in _run_response_middleware
    _response = await _response
  File "c:\users\feder\appdata\local\programs\python\python36\lib\site-packages\sanic_cors\extension.py", line 266, in unapplied_cors_response_middleware
    set_cors_headers(req, resp, context, res_options)
  File "c:\users\feder\appdata\local\programs\python\python36\lib\site-packages\sanic_cors\core.py", line 248, in set_cors_headers
    if resp.headers is None:
AttributeError: 'list' object has no attribute 'headers'
2019-06-24 23:19:21,114 [ERROR]  Exception occurred while handling uri: unknown
NoneType: None
2019-06-24 23:19:24,158 [ERROR]  Exception occurred in one of response middleware handlers
Traceback (most recent call last):
  File "c:\users\feder\appdata\local\programs\python\python36\lib\site-packages\sanic\app.py", line 958, in handle_request
    request, response
  File "c:\users\feder\appdata\local\programs\python\python36\lib\site-packages\spf\framework.py", line 543, in _run_response_middleware
    _response = await _response
  File "c:\users\feder\appdata\local\programs\python\python36\lib\site-packages\sanic_cors\extension.py", line 266, in unapplied_cors_response_middleware
    set_cors_headers(req, resp, context, res_options)
  File "c:\users\feder\appdata\local\programs\python\python36\lib\site-packages\sanic_cors\core.py", line 248, in set_cors_headers
    if resp.headers is None:
AttributeError: 'list' object has no attribute 'headers'
2019-06-24 23:20:02,788 [ERROR]  Exception occurred in one of response middleware handlers
Traceback (most recent call last):
  File "c:\users\feder\appdata\local\programs\python\python36\lib\site-packages\sanic\app.py", line 958, in handle_request
    request, response
  File "c:\users\feder\appdata\local\programs\python\python36\lib\site-packages\spf\framework.py", line 543, in _run_response_middleware
    _response = await _response
  File "c:\users\feder\appdata\local\programs\python\python36\lib\site-packages\sanic_cors\extension.py", line 266, in unapplied_cors_response_middleware
    set_cors_headers(req, resp, context, res_options)
  File "c:\users\feder\appdata\local\programs\python\python36\lib\site-packages\sanic_cors\core.py", line 248, in set_cors_headers
    if resp.headers is None:
AttributeError: 'list' object has no attribute 'headers'
2019-06-24 23:21:14,436 [ERROR]  Exception occurred in one of response middleware handlers
Traceback (most recent call last):
  File "c:\users\feder\appdata\local\programs\python\python36\lib\site-packages\sanic\app.py", line 958, in handle_request
    request, response
  File "c:\users\feder\appdata\local\programs\python\python36\lib\site-packages\spf\framework.py", line 543, in _run_response_middleware
    _response = await _response
  File "c:\users\feder\appdata\local\programs\python\python36\lib\site-packages\sanic_cors\extension.py", line 266, in unapplied_cors_response_middleware
    set_cors_headers(req, resp, context, res_options)
  File "c:\users\feder\appdata\local\programs\python\python36\lib\site-packages\sanic_cors\core.py", line 248, in set_cors_headers
    if resp.headers is None:
AttributeError: 'list' object has no attribute 'headers'
2019-06-24 23:21:33,384 [ERROR]  Exception occurred in one of response middleware handlers
Traceback (most recent call last):
  File "c:\users\feder\appdata\local\programs\python\python36\lib\site-packages\sanic\app.py", line 958, in handle_request
    request, response
  File "c:\users\feder\appdata\local\programs\python\python36\lib\site-packages\spf\framework.py", line 543, in _run_response_middleware
    _response = await _response
  File "c:\users\feder\appdata\local\programs\python\python36\lib\site-packages\sanic_cors\extension.py", line 266, in unapplied_cors_response_middleware
    set_cors_headers(req, resp, context, res_options)
  File "c:\users\feder\appdata\local\programs\python\python36\lib\site-packages\sanic_cors\core.py", line 248, in set_cors_headers
    if resp.headers is None:
AttributeError: 'list' object has no attribute 'headers'
2019-06-24 23:21:37,315 [ERROR]  Exception occurred in one of response middleware handlers
Traceback (most recent call last):
  File "c:\users\feder\appdata\local\programs\python\python36\lib\site-packages\sanic\app.py", line 958, in handle_request
    request, response
  File "c:\users\feder\appdata\local\programs\python\python36\lib\site-packages\spf\framework.py", line 543, in _run_response_middleware
    _response = await _response
  File "c:\users\feder\appdata\local\programs\python\python36\lib\site-packages\sanic_cors\extension.py", line 266, in unapplied_cors_response_middleware
    set_cors_headers(req, resp, context, res_options)
  File "c:\users\feder\appdata\local\programs\python\python36\lib\site-packages\sanic_cors\core.py", line 248, in set_cors_headers
    if resp.headers is None:
AttributeError: 'list' object has no attribute 'headers'
2019-06-24 23:22:33,970 [ERROR]  Exception occurred while handling uri: unknown
NoneType: None
2019-06-24 23:22:38,563 [ERROR]  Exception occurred in one of response middleware handlers
Traceback (most recent call last):
  File "c:\users\feder\appdata\local\programs\python\python36\lib\site-packages\sanic\app.py", line 958, in handle_request
    request, response
  File "c:\users\feder\appdata\local\programs\python\python36\lib\site-packages\spf\framework.py", line 543, in _run_response_middleware
    _response = await _response
  File "c:\users\feder\appdata\local\programs\python\python36\lib\site-packages\sanic_cors\extension.py", line 266, in unapplied_cors_response_middleware
    set_cors_headers(req, resp, context, res_options)
  File "c:\users\feder\appdata\local\programs\python\python36\lib\site-packages\sanic_cors\core.py", line 248, in set_cors_headers
    if resp.headers is None:
AttributeError: 'list' object has no attribute 'headers'
2019-06-24 23:23:05,313 [ERROR]  Exception occurred in one of response middleware handlers
Traceback (most recent call last):
  File "c:\users\feder\appdata\local\programs\python\python36\lib\site-packages\sanic\app.py", line 958, in handle_request
    request, response
  File "c:\users\feder\appdata\local\programs\python\python36\lib\site-packages\spf\framework.py", line 543, in _run_response_middleware
    _response = await _response
  File "c:\users\feder\appdata\local\programs\python\python36\lib\site-packages\sanic_cors\extension.py", line 266, in unapplied_cors_response_middleware
    set_cors_headers(req, resp, context, res_options)
  File "c:\users\feder\appdata\local\programs\python\python36\lib\site-packages\sanic_cors\core.py", line 248, in set_cors_headers
    if resp.headers is None:
AttributeError: 'list' object has no attribute 'headers'
2019-06-24 23:23:30,948 [ERROR]  Exception occurred in one of response middleware handlers
Traceback (most recent call last):
  File "c:\users\feder\appdata\local\programs\python\python36\lib\site-packages\sanic\app.py", line 958, in handle_request
    request, response
  File "c:\users\feder\appdata\local\programs\python\python36\lib\site-packages\spf\framework.py", line 543, in _run_response_middleware
    _response = await _response
  File "c:\users\feder\appdata\local\programs\python\python36\lib\site-packages\sanic_cors\extension.py", line 266, in unapplied_cors_response_middleware
    set_cors_headers(req, resp, context, res_options)
  File "c:\users\feder\appdata\local\programs\python\python36\lib\site-packages\sanic_cors\core.py", line 248, in set_cors_headers
    if resp.headers is None:
AttributeError: 'list' object has no attribute 'headers'
2019-06-24 23:24:44,188 [ERROR]  Exception occurred in one of response middleware handlers
Traceback (most recent call last):
  File "c:\users\feder\appdata\local\programs\python\python36\lib\site-packages\sanic\app.py", line 958, in handle_request
    request, response
  File "c:\users\feder\appdata\local\programs\python\python36\lib\site-packages\spf\framework.py", line 543, in _run_response_middleware
    _response = await _response
  File "c:\users\feder\appdata\local\programs\python\python36\lib\site-packages\sanic_cors\extension.py", line 266, in unapplied_cors_response_middleware
    set_cors_headers(req, resp, context, res_options)
  File "c:\users\feder\appdata\local\programs\python\python36\lib\site-packages\sanic_cors\core.py", line 248, in set_cors_headers
    if resp.headers is None:
AttributeError: 'list' object has no attribute 'headers'
2019-06-24 23:24:45,889 [ERROR]  Exception occurred in one of response middleware handlers
Traceback (most recent call last):
  File "c:\users\feder\appdata\local\programs\python\python36\lib\site-packages\sanic\app.py", line 958, in handle_request
    request, response
  File "c:\users\feder\appdata\local\programs\python\python36\lib\site-packages\spf\framework.py", line 543, in _run_response_middleware
    _response = await _response
  File "c:\users\feder\appdata\local\programs\python\python36\lib\site-packages\sanic_cors\extension.py", line 266, in unapplied_cors_response_middleware
    set_cors_headers(req, resp, context, res_options)
  File "c:\users\feder\appdata\local\programs\python\python36\lib\site-packages\sanic_cors\core.py", line 248, in set_cors_headers
    if resp.headers is None:
AttributeError: 'list' object has no attribute 'headers'
2019-06-24 23:25:23,376 [ERROR]  Exception occurred in one of response middleware handlers
Traceback (most recent call last):
  File "c:\users\feder\appdata\local\programs\python\python36\lib\site-packages\sanic\app.py", line 958, in handle_request
    request, response
  File "c:\users\feder\appdata\local\programs\python\python36\lib\site-packages\spf\framework.py", line 543, in _run_response_middleware
    _response = await _response
  File "c:\users\feder\appdata\local\programs\python\python36\lib\site-packages\sanic_cors\extension.py", line 266, in unapplied_cors_response_middleware
    set_cors_headers(req, resp, context, res_options)
  File "c:\users\feder\appdata\local\programs\python\python36\lib\site-packages\sanic_cors\core.py", line 248, in set_cors_headers
    if resp.headers is None:
AttributeError: 'list' object has no attribute 'headers'
2019-06-24 23:25:37,582 [ERROR]  Exception occurred in one of response middleware handlers
Traceback (most recent call last):
  File "c:\users\feder\appdata\local\programs\python\python36\lib\site-packages\sanic\app.py", line 958, in handle_request
    request, response
  File "c:\users\feder\appdata\local\programs\python\python36\lib\site-packages\spf\framework.py", line 543, in _run_response_middleware
    _response = await _response
  File "c:\users\feder\appdata\local\programs\python\python36\lib\site-packages\sanic_cors\extension.py", line 266, in unapplied_cors_response_middleware
    set_cors_headers(req, resp, context, res_options)
  File "c:\users\feder\appdata\local\programs\python\python36\lib\site-packages\sanic_cors\core.py", line 248, in set_cors_headers
    if resp.headers is None:
AttributeError: 'list' object has no attribute 'headers'
2019-06-24 23:25:49,416 [ERROR]  Exception occurred in one of response middleware handlers
Traceback (most recent call last):
  File "c:\users\feder\appdata\local\programs\python\python36\lib\site-packages\sanic\app.py", line 958, in handle_request
    request, response
  File "c:\users\feder\appdata\local\programs\python\python36\lib\site-packages\spf\framework.py", line 543, in _run_response_middleware
    _response = await _response
  File "c:\users\feder\appdata\local\programs\python\python36\lib\site-packages\sanic_cors\extension.py", line 266, in unapplied_cors_response_middleware
    set_cors_headers(req, resp, context, res_options)
  File "c:\users\feder\appdata\local\programs\python\python36\lib\site-packages\sanic_cors\core.py", line 248, in set_cors_headers
    if resp.headers is None:
AttributeError: 'list' object has no attribute 'headers'
2019-06-24 23:25:58,393 [ERROR]  Exception occurred in one of response middleware handlers
Traceback (most recent call last):
  File "c:\users\feder\appdata\local\programs\python\python36\lib\site-packages\sanic\app.py", line 958, in handle_request
    request, response
  File "c:\users\feder\appdata\local\programs\python\python36\lib\site-packages\spf\framework.py", line 543, in _run_response_middleware
    _response = await _response
  File "c:\users\feder\appdata\local\programs\python\python36\lib\site-packages\sanic_cors\extension.py", line 266, in unapplied_cors_response_middleware
    set_cors_headers(req, resp, context, res_options)
  File "c:\users\feder\appdata\local\programs\python\python36\lib\site-packages\sanic_cors\core.py", line 248, in set_cors_headers
    if resp.headers is None:
AttributeError: 'list' object has no attribute 'headers'
2019-06-24 23:26:33,484 [ERROR]  Exception occurred in one of response middleware handlers
Traceback (most recent call last):
  File "c:\users\feder\appdata\local\programs\python\python36\lib\site-packages\sanic\app.py", line 958, in handle_request
    request, response
  File "c:\users\feder\appdata\local\programs\python\python36\lib\site-packages\spf\framework.py", line 543, in _run_response_middleware
    _response = await _response
  File "c:\users\feder\appdata\local\programs\python\python36\lib\site-packages\sanic_cors\extension.py", line 266, in unapplied_cors_response_middleware
    set_cors_headers(req, resp, context, res_options)
  File "c:\users\feder\appdata\local\programs\python\python36\lib\site-packages\sanic_cors\core.py", line 248, in set_cors_headers
    if resp.headers is None:
AttributeError: 'list' object has no attribute 'headers'
2019-06-24 23:26:52,393 [ERROR]  Exception occurred in one of response middleware handlers
Traceback (most recent call last):
  File "c:\users\feder\appdata\local\programs\python\python36\lib\site-packages\sanic\app.py", line 958, in handle_request
    request, response
  File "c:\users\feder\appdata\local\programs\python\python36\lib\site-packages\spf\framework.py", line 543, in _run_response_middleware
    _response = await _response
  File "c:\users\feder\appdata\local\programs\python\python36\lib\site-packages\sanic_cors\extension.py", line 266, in unapplied_cors_response_middleware
    set_cors_headers(req, resp, context, res_options)
  File "c:\users\feder\appdata\local\programs\python\python36\lib\site-packages\sanic_cors\core.py", line 248, in set_cors_headers
    if resp.headers is None:
AttributeError: 'list' object has no attribute 'headers'
2019-06-24 23:27:31,290 [ERROR]  Exception occurred in one of response middleware handlers
Traceback (most recent call last):
  File "c:\users\feder\appdata\local\programs\python\python36\lib\site-packages\sanic\app.py", line 958, in handle_request
    request, response
  File "c:\users\feder\appdata\local\programs\python\python36\lib\site-packages\spf\framework.py", line 543, in _run_response_middleware
    _response = await _response
  File "c:\users\feder\appdata\local\programs\python\python36\lib\site-packages\sanic_cors\extension.py", line 266, in unapplied_cors_response_middleware
    set_cors_headers(req, resp, context, res_options)
  File "c:\users\feder\appdata\local\programs\python\python36\lib\site-packages\sanic_cors\core.py", line 248, in set_cors_headers
    if resp.headers is None:
AttributeError: 'list' object has no attribute 'headers'
2019-06-24 23:28:12,403 [ERROR]  Exception occurred in one of response middleware handlers
Traceback (most recent call last):
  File "c:\users\feder\appdata\local\programs\python\python36\lib\site-packages\sanic\app.py", line 958, in handle_request
    request, response
  File "c:\users\feder\appdata\local\programs\python\python36\lib\site-packages\spf\framework.py", line 543, in _run_response_middleware
    _response = await _response
  File "c:\users\feder\appdata\local\programs\python\python36\lib\site-packages\sanic_cors\extension.py", line 266, in unapplied_cors_response_middleware
    set_cors_headers(req, resp, context, res_options)
  File "c:\users\feder\appdata\local\programs\python\python36\lib\site-packages\sanic_cors\core.py", line 248, in set_cors_headers
    if resp.headers is None:
AttributeError: 'list' object has no attribute 'headers'
2019-06-24 23:28:14,370 [ERROR]  Exception occurred in one of response middleware handlers
Traceback (most recent call last):
  File "c:\users\feder\appdata\local\programs\python\python36\lib\site-packages\sanic\app.py", line 958, in handle_request
    request, response
  File "c:\users\feder\appdata\local\programs\python\python36\lib\site-packages\spf\framework.py", line 543, in _run_response_middleware
    _response = await _response
  File "c:\users\feder\appdata\local\programs\python\python36\lib\site-packages\sanic_cors\extension.py", line 266, in unapplied_cors_response_middleware
    set_cors_headers(req, resp, context, res_options)
  File "c:\users\feder\appdata\local\programs\python\python36\lib\site-packages\sanic_cors\core.py", line 248, in set_cors_headers
    if resp.headers is None:
AttributeError: 'list' object has no attribute 'headers'
2019-06-24 23:28:23,596 [ERROR]  Exception occurred in one of response middleware handlers
Traceback (most recent call last):
  File "c:\users\feder\appdata\local\programs\python\python36\lib\site-packages\sanic\app.py", line 958, in handle_request
    request, response
  File "c:\users\feder\appdata\local\programs\python\python36\lib\site-packages\spf\framework.py", line 543, in _run_response_middleware
    _response = await _response
  File "c:\users\feder\appdata\local\programs\python\python36\lib\site-packages\sanic_cors\extension.py", line 266, in unapplied_cors_response_middleware
    set_cors_headers(req, resp, context, res_options)
  File "c:\users\feder\appdata\local\programs\python\python36\lib\site-packages\sanic_cors\core.py", line 248, in set_cors_headers
    if resp.headers is None:
AttributeError: 'list' object has no attribute 'headers'
2019-06-24 23:28:52,829 [ERROR]  Exception occurred in one of response middleware handlers
Traceback (most recent call last):
  File "c:\users\feder\appdata\local\programs\python\python36\lib\site-packages\sanic\app.py", line 958, in handle_request
    request, response
  File "c:\users\feder\appdata\local\programs\python\python36\lib\site-packages\spf\framework.py", line 543, in _run_response_middleware
    _response = await _response
  File "c:\users\feder\appdata\local\programs\python\python36\lib\site-packages\sanic_cors\extension.py", line 266, in unapplied_cors_response_middleware
    set_cors_headers(req, resp, context, res_options)
  File "c:\users\feder\appdata\local\programs\python\python36\lib\site-packages\sanic_cors\core.py", line 248, in set_cors_headers
    if resp.headers is None:
AttributeError: 'list' object has no attribute 'headers'
2019-06-24 23:29:01,526 [ERROR]  Exception occurred in one of response middleware handlers
Traceback (most recent call last):
  File "c:\users\feder\appdata\local\programs\python\python36\lib\site-packages\sanic\app.py", line 958, in handle_request
    request, response
  File "c:\users\feder\appdata\local\programs\python\python36\lib\site-packages\spf\framework.py", line 543, in _run_response_middleware
    _response = await _response
  File "c:\users\feder\appdata\local\programs\python\python36\lib\site-packages\sanic_cors\extension.py", line 266, in unapplied_cors_response_middleware
    set_cors_headers(req, resp, context, res_options)
  File "c:\users\feder\appdata\local\programs\python\python36\lib\site-packages\sanic_cors\core.py", line 248, in set_cors_headers
    if resp.headers is None:
AttributeError: 'list' object has no attribute 'headers'
2019-06-24 23:29:09,001 [ERROR]  Exception occurred in one of response middleware handlers
Traceback (most recent call last):
  File "c:\users\feder\appdata\local\programs\python\python36\lib\site-packages\sanic\app.py", line 958, in handle_request
    request, response
  File "c:\users\feder\appdata\local\programs\python\python36\lib\site-packages\spf\framework.py", line 543, in _run_response_middleware
    _response = await _response
  File "c:\users\feder\appdata\local\programs\python\python36\lib\site-packages\sanic_cors\extension.py", line 266, in unapplied_cors_response_middleware
    set_cors_headers(req, resp, context, res_options)
  File "c:\users\feder\appdata\local\programs\python\python36\lib\site-packages\sanic_cors\core.py", line 248, in set_cors_headers
    if resp.headers is None:
AttributeError: 'list' object has no attribute 'headers'
2019-06-24 23:29:22,195 [ERROR]  Exception occurred in one of response middleware handlers
Traceback (most recent call last):
  File "c:\users\feder\appdata\local\programs\python\python36\lib\site-packages\sanic\app.py", line 958, in handle_request
    request, response
  File "c:\users\feder\appdata\local\programs\python\python36\lib\site-packages\spf\framework.py", line 543, in _run_response_middleware
    _response = await _response
  File "c:\users\feder\appdata\local\programs\python\python36\lib\site-packages\sanic_cors\extension.py", line 266, in unapplied_cors_response_middleware
    set_cors_headers(req, resp, context, res_options)
  File "c:\users\feder\appdata\local\programs\python\python36\lib\site-packages\sanic_cors\core.py", line 248, in set_cors_headers
    if resp.headers is None:
AttributeError: 'list' object has no attribute 'headers'
2019-06-24 23:29:35,836 [ERROR]  Exception occurred in one of response middleware handlers
Traceback (most recent call last):
  File "c:\users\feder\appdata\local\programs\python\python36\lib\site-packages\sanic\app.py", line 958, in handle_request
    request, response
  File "c:\users\feder\appdata\local\programs\python\python36\lib\site-packages\spf\framework.py", line 543, in _run_response_middleware
    _response = await _response
  File "c:\users\feder\appdata\local\programs\python\python36\lib\site-packages\sanic_cors\extension.py", line 266, in unapplied_cors_response_middleware
    set_cors_headers(req, resp, context, res_options)
  File "c:\users\feder\appdata\local\programs\python\python36\lib\site-packages\sanic_cors\core.py", line 248, in set_cors_headers
    if resp.headers is None:
AttributeError: 'list' object has no attribute 'headers'
2019-06-24 23:30:01,911 [ERROR]  Exception occurred in one of response middleware handlers
Traceback (most recent call last):
  File "c:\users\feder\appdata\local\programs\python\python36\lib\site-packages\sanic\app.py", line 958, in handle_request
    request, response
  File "c:\users\feder\appdata\local\programs\python\python36\lib\site-packages\spf\framework.py", line 543, in _run_response_middleware
    _response = await _response
  File "c:\users\feder\appdata\local\programs\python\python36\lib\site-packages\sanic_cors\extension.py", line 266, in unapplied_cors_response_middleware
    set_cors_headers(req, resp, context, res_options)
  File "c:\users\feder\appdata\local\programs\python\python36\lib\site-packages\sanic_cors\core.py", line 248, in set_cors_headers
    if resp.headers is None:
AttributeError: 'list' object has no attribute 'headers'
2019-06-24 23:30:14,902 [ERROR]  Exception occurred in one of response middleware handlers
Traceback (most recent call last):
  File "c:\users\feder\appdata\local\programs\python\python36\lib\site-packages\sanic\app.py", line 958, in handle_request
    request, response
  File "c:\users\feder\appdata\local\programs\python\python36\lib\site-packages\spf\framework.py", line 543, in _run_response_middleware
    _response = await _response
  File "c:\users\feder\appdata\local\programs\python\python36\lib\site-packages\sanic_cors\extension.py", line 266, in unapplied_cors_response_middleware
    set_cors_headers(req, resp, context, res_options)
  File "c:\users\feder\appdata\local\programs\python\python36\lib\site-packages\sanic_cors\core.py", line 248, in set_cors_headers
    if resp.headers is None:
AttributeError: 'list' object has no attribute 'headers'
2019-06-24 23:30:20,257 [ERROR]  Exception occurred in one of response middleware handlers
Traceback (most recent call last):
  File "c:\users\feder\appdata\local\programs\python\python36\lib\site-packages\sanic\app.py", line 958, in handle_request
    request, response
  File "c:\users\feder\appdata\local\programs\python\python36\lib\site-packages\spf\framework.py", line 543, in _run_response_middleware
    _response = await _response
  File "c:\users\feder\appdata\local\programs\python\python36\lib\site-packages\sanic_cors\extension.py", line 266, in unapplied_cors_response_middleware
    set_cors_headers(req, resp, context, res_options)
  File "c:\users\feder\appdata\local\programs\python\python36\lib\site-packages\sanic_cors\core.py", line 248, in set_cors_headers
    if resp.headers is None:
AttributeError: 'list' object has no attribute 'headers'
2019-06-24 23:30:45,847 [ERROR]  Exception occurred in one of response middleware handlers
Traceback (most recent call last):
  File "c:\users\feder\appdata\local\programs\python\python36\lib\site-packages\sanic\app.py", line 958, in handle_request
    request, response
  File "c:\users\feder\appdata\local\programs\python\python36\lib\site-packages\spf\framework.py", line 543, in _run_response_middleware
    _response = await _response
  File "c:\users\feder\appdata\local\programs\python\python36\lib\site-packages\sanic_cors\extension.py", line 266, in unapplied_cors_response_middleware
    set_cors_headers(req, resp, context, res_options)
  File "c:\users\feder\appdata\local\programs\python\python36\lib\site-packages\sanic_cors\core.py", line 248, in set_cors_headers
    if resp.headers is None:
AttributeError: 'list' object has no attribute 'headers'
2019-06-24 23:30:51,065 [ERROR]  Exception occurred in one of response middleware handlers
Traceback (most recent call last):
  File "c:\users\feder\appdata\local\programs\python\python36\lib\site-packages\sanic\app.py", line 958, in handle_request
    request, response
  File "c:\users\feder\appdata\local\programs\python\python36\lib\site-packages\spf\framework.py", line 543, in _run_response_middleware
    _response = await _response
  File "c:\users\feder\appdata\local\programs\python\python36\lib\site-packages\sanic_cors\extension.py", line 266, in unapplied_cors_response_middleware
    set_cors_headers(req, resp, context, res_options)
  File "c:\users\feder\appdata\local\programs\python\python36\lib\site-packages\sanic_cors\core.py", line 248, in set_cors_headers
    if resp.headers is None:
AttributeError: 'list' object has no attribute 'headers'
2019-06-24 23:30:57,229 [ERROR]  Exception occurred in one of response middleware handlers
Traceback (most recent call last):
  File "c:\users\feder\appdata\local\programs\python\python36\lib\site-packages\sanic\app.py", line 958, in handle_request
    request, response
  File "c:\users\feder\appdata\local\programs\python\python36\lib\site-packages\spf\framework.py", line 543, in _run_response_middleware
    _response = await _response
  File "c:\users\feder\appdata\local\programs\python\python36\lib\site-packages\sanic_cors\extension.py", line 266, in unapplied_cors_response_middleware
    set_cors_headers(req, resp, context, res_options)
  File "c:\users\feder\appdata\local\programs\python\python36\lib\site-packages\sanic_cors\core.py", line 248, in set_cors_headers
    if resp.headers is None:
AttributeError: 'list' object has no attribute 'headers'
2019-06-24 23:30:58,818 [ERROR]  Exception occurred in one of response middleware handlers
Traceback (most recent call last):
  File "c:\users\feder\appdata\local\programs\python\python36\lib\site-packages\sanic\app.py", line 958, in handle_request
    request, response
  File "c:\users\feder\appdata\local\programs\python\python36\lib\site-packages\spf\framework.py", line 543, in _run_response_middleware
    _response = await _response
  File "c:\users\feder\appdata\local\programs\python\python36\lib\site-packages\sanic_cors\extension.py", line 266, in unapplied_cors_response_middleware
    set_cors_headers(req, resp, context, res_options)
  File "c:\users\feder\appdata\local\programs\python\python36\lib\site-packages\sanic_cors\core.py", line 248, in set_cors_headers
    if resp.headers is None:
AttributeError: 'list' object has no attribute 'headers'
2019-06-24 23:32:06,692 [ERROR]  Exception occurred in one of response middleware handlers
Traceback (most recent call last):
  File "c:\users\feder\appdata\local\programs\python\python36\lib\site-packages\sanic\app.py", line 958, in handle_request
    request, response
  File "c:\users\feder\appdata\local\programs\python\python36\lib\site-packages\spf\framework.py", line 543, in _run_response_middleware
    _response = await _response
  File "c:\users\feder\appdata\local\programs\python\python36\lib\site-packages\sanic_cors\extension.py", line 266, in unapplied_cors_response_middleware
    set_cors_headers(req, resp, context, res_options)
  File "c:\users\feder\appdata\local\programs\python\python36\lib\site-packages\sanic_cors\core.py", line 248, in set_cors_headers
    if resp.headers is None:
AttributeError: 'list' object has no attribute 'headers'
2019-06-24 23:32:08,550 [ERROR]  Exception occurred in one of response middleware handlers
Traceback (most recent call last):
  File "c:\users\feder\appdata\local\programs\python\python36\lib\site-packages\sanic\app.py", line 958, in handle_request
    request, response
  File "c:\users\feder\appdata\local\programs\python\python36\lib\site-packages\spf\framework.py", line 543, in _run_response_middleware
    _response = await _response
  File "c:\users\feder\appdata\local\programs\python\python36\lib\site-packages\sanic_cors\extension.py", line 266, in unapplied_cors_response_middleware
    set_cors_headers(req, resp, context, res_options)
  File "c:\users\feder\appdata\local\programs\python\python36\lib\site-packages\sanic_cors\core.py", line 248, in set_cors_headers
    if resp.headers is None:
AttributeError: 'list' object has no attribute 'headers'
2019-06-24 23:32:25,829 [ERROR]  Exception occurred in one of response middleware handlers
Traceback (most recent call last):
  File "c:\users\feder\appdata\local\programs\python\python36\lib\site-packages\sanic\app.py", line 958, in handle_request
    request, response
  File "c:\users\feder\appdata\local\programs\python\python36\lib\site-packages\spf\framework.py", line 543, in _run_response_middleware
    _response = await _response
  File "c:\users\feder\appdata\local\programs\python\python36\lib\site-packages\sanic_cors\extension.py", line 266, in unapplied_cors_response_middleware
    set_cors_headers(req, resp, context, res_options)
  File "c:\users\feder\appdata\local\programs\python\python36\lib\site-packages\sanic_cors\core.py", line 248, in set_cors_headers
    if resp.headers is None:
AttributeError: 'list' object has no attribute 'headers'
2019-06-24 23:32:39,867 [ERROR]  Exception occurred in one of response middleware handlers
Traceback (most recent call last):
  File "c:\users\feder\appdata\local\programs\python\python36\lib\site-packages\sanic\app.py", line 958, in handle_request
    request, response
  File "c:\users\feder\appdata\local\programs\python\python36\lib\site-packages\spf\framework.py", line 543, in _run_response_middleware
    _response = await _response
  File "c:\users\feder\appdata\local\programs\python\python36\lib\site-packages\sanic_cors\extension.py", line 266, in unapplied_cors_response_middleware
    set_cors_headers(req, resp, context, res_options)
  File "c:\users\feder\appdata\local\programs\python\python36\lib\site-packages\sanic_cors\core.py", line 248, in set_cors_headers
    if resp.headers is None:
AttributeError: 'list' object has no attribute 'headers'
2019-06-24 23:32:56,039 [ERROR]  Exception occurred in one of response middleware handlers
Traceback (most recent call last):
  File "c:\users\feder\appdata\local\programs\python\python36\lib\site-packages\sanic\app.py", line 958, in handle_request
    request, response
  File "c:\users\feder\appdata\local\programs\python\python36\lib\site-packages\spf\framework.py", line 543, in _run_response_middleware
    _response = await _response
  File "c:\users\feder\appdata\local\programs\python\python36\lib\site-packages\sanic_cors\extension.py", line 266, in unapplied_cors_response_middleware
    set_cors_headers(req, resp, context, res_options)
  File "c:\users\feder\appdata\local\programs\python\python36\lib\site-packages\sanic_cors\core.py", line 248, in set_cors_headers
    if resp.headers is None:
AttributeError: 'list' object has no attribute 'headers'
2019-06-24 23:32:58,096 [ERROR]  Exception occurred in one of response middleware handlers
Traceback (most recent call last):
  File "c:\users\feder\appdata\local\programs\python\python36\lib\site-packages\sanic\app.py", line 958, in handle_request
    request, response
  File "c:\users\feder\appdata\local\programs\python\python36\lib\site-packages\spf\framework.py", line 543, in _run_response_middleware
    _response = await _response
  File "c:\users\feder\appdata\local\programs\python\python36\lib\site-packages\sanic_cors\extension.py", line 266, in unapplied_cors_response_middleware
    set_cors_headers(req, resp, context, res_options)
  File "c:\users\feder\appdata\local\programs\python\python36\lib\site-packages\sanic_cors\core.py", line 248, in set_cors_headers
    if resp.headers is None:
AttributeError: 'list' object has no attribute 'headers'
2019-06-24 23:33:30,025 [ERROR]  Exception occurred in one of response middleware handlers
Traceback (most recent call last):
  File "c:\users\feder\appdata\local\programs\python\python36\lib\site-packages\sanic\app.py", line 958, in handle_request
    request, response
  File "c:\users\feder\appdata\local\programs\python\python36\lib\site-packages\spf\framework.py", line 543, in _run_response_middleware
    _response = await _response
  File "c:\users\feder\appdata\local\programs\python\python36\lib\site-packages\sanic_cors\extension.py", line 266, in unapplied_cors_response_middleware
    set_cors_headers(req, resp, context, res_options)
  File "c:\users\feder\appdata\local\programs\python\python36\lib\site-packages\sanic_cors\core.py", line 248, in set_cors_headers
    if resp.headers is None:
AttributeError: 'list' object has no attribute 'headers'
2019-06-24 23:33:36,154 [ERROR]  Exception occurred in one of response middleware handlers
Traceback (most recent call last):
  File "c:\users\feder\appdata\local\programs\python\python36\lib\site-packages\sanic\app.py", line 958, in handle_request
    request, response
  File "c:\users\feder\appdata\local\programs\python\python36\lib\site-packages\spf\framework.py", line 543, in _run_response_middleware
    _response = await _response
  File "c:\users\feder\appdata\local\programs\python\python36\lib\site-packages\sanic_cors\extension.py", line 266, in unapplied_cors_response_middleware
    set_cors_headers(req, resp, context, res_options)
  File "c:\users\feder\appdata\local\programs\python\python36\lib\site-packages\sanic_cors\core.py", line 248, in set_cors_headers
    if resp.headers is None:
AttributeError: 'list' object has no attribute 'headers'
2019-06-24 23:34:03,269 [ERROR]  Exception occurred in one of response middleware handlers
Traceback (most recent call last):
  File "c:\users\feder\appdata\local\programs\python\python36\lib\site-packages\sanic\app.py", line 958, in handle_request
    request, response
  File "c:\users\feder\appdata\local\programs\python\python36\lib\site-packages\spf\framework.py", line 543, in _run_response_middleware
    _response = await _response
  File "c:\users\feder\appdata\local\programs\python\python36\lib\site-packages\sanic_cors\extension.py", line 266, in unapplied_cors_response_middleware
    set_cors_headers(req, resp, context, res_options)
  File "c:\users\feder\appdata\local\programs\python\python36\lib\site-packages\sanic_cors\core.py", line 248, in set_cors_headers
    if resp.headers is None:
AttributeError: 'list' object has no attribute 'headers'
2019-06-24 23:34:14,631 [ERROR]  Exception occurred in one of response middleware handlers
Traceback (most recent call last):
  File "c:\users\feder\appdata\local\programs\python\python36\lib\site-packages\sanic\app.py", line 958, in handle_request
    request, response
  File "c:\users\feder\appdata\local\programs\python\python36\lib\site-packages\spf\framework.py", line 543, in _run_response_middleware
    _response = await _response
  File "c:\users\feder\appdata\local\programs\python\python36\lib\site-packages\sanic_cors\extension.py", line 266, in unapplied_cors_response_middleware
    set_cors_headers(req, resp, context, res_options)
  File "c:\users\feder\appdata\local\programs\python\python36\lib\site-packages\sanic_cors\core.py", line 248, in set_cors_headers
    if resp.headers is None:
AttributeError: 'list' object has no attribute 'headers'
2019-06-24 23:36:32,869 [ERROR]  Exception occurred in one of response middleware handlers
Traceback (most recent call last):
  File "c:\users\feder\appdata\local\programs\python\python36\lib\site-packages\sanic\app.py", line 958, in handle_request
    request, response
  File "c:\users\feder\appdata\local\programs\python\python36\lib\site-packages\spf\framework.py", line 543, in _run_response_middleware
    _response = await _response
  File "c:\users\feder\appdata\local\programs\python\python36\lib\site-packages\sanic_cors\extension.py", line 266, in unapplied_cors_response_middleware
    set_cors_headers(req, resp, context, res_options)
  File "c:\users\feder\appdata\local\programs\python\python36\lib\site-packages\sanic_cors\core.py", line 248, in set_cors_headers
    if resp.headers is None:
AttributeError: 'list' object has no attribute 'headers'
2019-06-24 23:36:49,045 [ERROR]  Exception occurred in one of response middleware handlers
Traceback (most recent call last):
  File "c:\users\feder\appdata\local\programs\python\python36\lib\site-packages\sanic\app.py", line 958, in handle_request
    request, response
  File "c:\users\feder\appdata\local\programs\python\python36\lib\site-packages\spf\framework.py", line 543, in _run_response_middleware
    _response = await _response
  File "c:\users\feder\appdata\local\programs\python\python36\lib\site-packages\sanic_cors\extension.py", line 266, in unapplied_cors_response_middleware
    set_cors_headers(req, resp, context, res_options)
  File "c:\users\feder\appdata\local\programs\python\python36\lib\site-packages\sanic_cors\core.py", line 248, in set_cors_headers
    if resp.headers is None:
AttributeError: 'list' object has no attribute 'headers'
2019-06-24 23:38:48,366 [ERROR]  Exception occurred in one of response middleware handlers
Traceback (most recent call last):
  File "c:\users\feder\appdata\local\programs\python\python36\lib\site-packages\sanic\app.py", line 958, in handle_request
    request, response
  File "c:\users\feder\appdata\local\programs\python\python36\lib\site-packages\spf\framework.py", line 543, in _run_response_middleware
    _response = await _response
  File "c:\users\feder\appdata\local\programs\python\python36\lib\site-packages\sanic_cors\extension.py", line 266, in unapplied_cors_response_middleware
    set_cors_headers(req, resp, context, res_options)
  File "c:\users\feder\appdata\local\programs\python\python36\lib\site-packages\sanic_cors\core.py", line 248, in set_cors_headers
    if resp.headers is None:
AttributeError: 'list' object has no attribute 'headers'
2019-06-24 23:43:06,207 [ERROR]  Exception occurred in one of response middleware handlers
Traceback (most recent call last):
  File "c:\users\feder\appdata\local\programs\python\python36\lib\site-packages\sanic\app.py", line 958, in handle_request
    request, response
  File "c:\users\feder\appdata\local\programs\python\python36\lib\site-packages\spf\framework.py", line 543, in _run_response_middleware
    _response = await _response
  File "c:\users\feder\appdata\local\programs\python\python36\lib\site-packages\sanic_cors\extension.py", line 266, in unapplied_cors_response_middleware
    set_cors_headers(req, resp, context, res_options)
  File "c:\users\feder\appdata\local\programs\python\python36\lib\site-packages\sanic_cors\core.py", line 248, in set_cors_headers
    if resp.headers is None:
AttributeError: 'list' object has no attribute 'headers'
2019-06-24 23:43:09,380 [ERROR]  Exception occurred in one of response middleware handlers
Traceback (most recent call last):
  File "c:\users\feder\appdata\local\programs\python\python36\lib\site-packages\sanic\app.py", line 958, in handle_request
    request, response
  File "c:\users\feder\appdata\local\programs\python\python36\lib\site-packages\spf\framework.py", line 543, in _run_response_middleware
    _response = await _response
  File "c:\users\feder\appdata\local\programs\python\python36\lib\site-packages\sanic_cors\extension.py", line 266, in unapplied_cors_response_middleware
    set_cors_headers(req, resp, context, res_options)
  File "c:\users\feder\appdata\local\programs\python\python36\lib\site-packages\sanic_cors\core.py", line 248, in set_cors_headers
    if resp.headers is None:
AttributeError: 'list' object has no attribute 'headers'
2019-06-24 23:44:06,801 [ERROR]  Exception occurred while handling uri: unknown
NoneType: None
2019-06-24 23:46:17,630 [ERROR]  Exception occurred in one of response middleware handlers
Traceback (most recent call last):
  File "c:\users\feder\appdata\local\programs\python\python36\lib\site-packages\sanic\app.py", line 958, in handle_request
    request, response
  File "c:\users\feder\appdata\local\programs\python\python36\lib\site-packages\spf\framework.py", line 543, in _run_response_middleware
    _response = await _response
  File "c:\users\feder\appdata\local\programs\python\python36\lib\site-packages\sanic_cors\extension.py", line 266, in unapplied_cors_response_middleware
    set_cors_headers(req, resp, context, res_options)
  File "c:\users\feder\appdata\local\programs\python\python36\lib\site-packages\sanic_cors\core.py", line 248, in set_cors_headers
    if resp.headers is None:
AttributeError: 'list' object has no attribute 'headers'
2019-06-24 23:46:20,192 [ERROR]  Exception occurred in one of response middleware handlers
Traceback (most recent call last):
  File "c:\users\feder\appdata\local\programs\python\python36\lib\site-packages\sanic\app.py", line 958, in handle_request
    request, response
  File "c:\users\feder\appdata\local\programs\python\python36\lib\site-packages\spf\framework.py", line 543, in _run_response_middleware
    _response = await _response
  File "c:\users\feder\appdata\local\programs\python\python36\lib\site-packages\sanic_cors\extension.py", line 266, in unapplied_cors_response_middleware
    set_cors_headers(req, resp, context, res_options)
  File "c:\users\feder\appdata\local\programs\python\python36\lib\site-packages\sanic_cors\core.py", line 248, in set_cors_headers
    if resp.headers is None:
AttributeError: 'list' object has no attribute 'headers'
2019-06-24 23:46:44,125 [ERROR]  Exception occurred in one of response middleware handlers
Traceback (most recent call last):
  File "c:\users\feder\appdata\local\programs\python\python36\lib\site-packages\sanic\app.py", line 958, in handle_request
    request, response
  File "c:\users\feder\appdata\local\programs\python\python36\lib\site-packages\spf\framework.py", line 543, in _run_response_middleware
    _response = await _response
  File "c:\users\feder\appdata\local\programs\python\python36\lib\site-packages\sanic_cors\extension.py", line 266, in unapplied_cors_response_middleware
    set_cors_headers(req, resp, context, res_options)
  File "c:\users\feder\appdata\local\programs\python\python36\lib\site-packages\sanic_cors\core.py", line 248, in set_cors_headers
    if resp.headers is None:
AttributeError: 'list' object has no attribute 'headers'
2019-06-24 23:47:31,561 [ERROR]  Exception occurred in one of response middleware handlers
Traceback (most recent call last):
  File "c:\users\feder\appdata\local\programs\python\python36\lib\site-packages\sanic\app.py", line 958, in handle_request
    request, response
  File "c:\users\feder\appdata\local\programs\python\python36\lib\site-packages\spf\framework.py", line 543, in _run_response_middleware
    _response = await _response
  File "c:\users\feder\appdata\local\programs\python\python36\lib\site-packages\sanic_cors\extension.py", line 266, in unapplied_cors_response_middleware
    set_cors_headers(req, resp, context, res_options)
  File "c:\users\feder\appdata\local\programs\python\python36\lib\site-packages\sanic_cors\core.py", line 248, in set_cors_headers
    if resp.headers is None:
AttributeError: 'list' object has no attribute 'headers'
2019-06-24 23:49:48,858 [ERROR]  Exception occurred in one of response middleware handlers
Traceback (most recent call last):
  File "c:\users\feder\appdata\local\programs\python\python36\lib\site-packages\sanic\app.py", line 958, in handle_request
    request, response
  File "c:\users\feder\appdata\local\programs\python\python36\lib\site-packages\spf\framework.py", line 543, in _run_response_middleware
    _response = await _response
  File "c:\users\feder\appdata\local\programs\python\python36\lib\site-packages\sanic_cors\extension.py", line 266, in unapplied_cors_response_middleware
    set_cors_headers(req, resp, context, res_options)
  File "c:\users\feder\appdata\local\programs\python\python36\lib\site-packages\sanic_cors\core.py", line 248, in set_cors_headers
    if resp.headers is None:
AttributeError: 'list' object has no attribute 'headers'
2019-06-24 23:49:53,252 [ERROR]  Exception occurred in one of response middleware handlers
Traceback (most recent call last):
  File "c:\users\feder\appdata\local\programs\python\python36\lib\site-packages\sanic\app.py", line 958, in handle_request
    request, response
  File "c:\users\feder\appdata\local\programs\python\python36\lib\site-packages\spf\framework.py", line 543, in _run_response_middleware
    _response = await _response
  File "c:\users\feder\appdata\local\programs\python\python36\lib\site-packages\sanic_cors\extension.py", line 266, in unapplied_cors_response_middleware
    set_cors_headers(req, resp, context, res_options)
  File "c:\users\feder\appdata\local\programs\python\python36\lib\site-packages\sanic_cors\core.py", line 248, in set_cors_headers
    if resp.headers is None:
AttributeError: 'list' object has no attribute 'headers'
2019-06-24 23:50:32,741 [ERROR]  Exception occurred in one of response middleware handlers
Traceback (most recent call last):
  File "c:\users\feder\appdata\local\programs\python\python36\lib\site-packages\sanic\app.py", line 958, in handle_request
    request, response
  File "c:\users\feder\appdata\local\programs\python\python36\lib\site-packages\spf\framework.py", line 543, in _run_response_middleware
    _response = await _response
  File "c:\users\feder\appdata\local\programs\python\python36\lib\site-packages\sanic_cors\extension.py", line 266, in unapplied_cors_response_middleware
    set_cors_headers(req, resp, context, res_options)
  File "c:\users\feder\appdata\local\programs\python\python36\lib\site-packages\sanic_cors\core.py", line 248, in set_cors_headers
    if resp.headers is None:
AttributeError: 'list' object has no attribute 'headers'
2019-06-24 23:51:31,317 [ERROR]  Exception occurred in one of response middleware handlers
Traceback (most recent call last):
  File "c:\users\feder\appdata\local\programs\python\python36\lib\site-packages\sanic\app.py", line 958, in handle_request
    request, response
  File "c:\users\feder\appdata\local\programs\python\python36\lib\site-packages\spf\framework.py", line 543, in _run_response_middleware
    _response = await _response
  File "c:\users\feder\appdata\local\programs\python\python36\lib\site-packages\sanic_cors\extension.py", line 266, in unapplied_cors_response_middleware
    set_cors_headers(req, resp, context, res_options)
  File "c:\users\feder\appdata\local\programs\python\python36\lib\site-packages\sanic_cors\core.py", line 248, in set_cors_headers
    if resp.headers is None:
AttributeError: 'list' object has no attribute 'headers'
2019-06-24 23:51:53,850 [ERROR]  Exception occurred in one of response middleware handlers
Traceback (most recent call last):
  File "c:\users\feder\appdata\local\programs\python\python36\lib\site-packages\sanic\app.py", line 958, in handle_request
    request, response
  File "c:\users\feder\appdata\local\programs\python\python36\lib\site-packages\spf\framework.py", line 543, in _run_response_middleware
    _response = await _response
  File "c:\users\feder\appdata\local\programs\python\python36\lib\site-packages\sanic_cors\extension.py", line 266, in unapplied_cors_response_middleware
    set_cors_headers(req, resp, context, res_options)
  File "c:\users\feder\appdata\local\programs\python\python36\lib\site-packages\sanic_cors\core.py", line 248, in set_cors_headers
    if resp.headers is None:
AttributeError: 'list' object has no attribute 'headers'
2019-06-24 23:52:16,549 [ERROR]  Exception occurred in one of response middleware handlers
Traceback (most recent call last):
  File "c:\users\feder\appdata\local\programs\python\python36\lib\site-packages\sanic\app.py", line 958, in handle_request
    request, response
  File "c:\users\feder\appdata\local\programs\python\python36\lib\site-packages\spf\framework.py", line 543, in _run_response_middleware
    _response = await _response
  File "c:\users\feder\appdata\local\programs\python\python36\lib\site-packages\sanic_cors\extension.py", line 266, in unapplied_cors_response_middleware
    set_cors_headers(req, resp, context, res_options)
  File "c:\users\feder\appdata\local\programs\python\python36\lib\site-packages\sanic_cors\core.py", line 248, in set_cors_headers
    if resp.headers is None:
AttributeError: 'list' object has no attribute 'headers'
2019-06-24 23:53:16,742 [ERROR]  Exception occurred in one of response middleware handlers
Traceback (most recent call last):
  File "c:\users\feder\appdata\local\programs\python\python36\lib\site-packages\sanic\app.py", line 958, in handle_request
    request, response
  File "c:\users\feder\appdata\local\programs\python\python36\lib\site-packages\spf\framework.py", line 543, in _run_response_middleware
    _response = await _response
  File "c:\users\feder\appdata\local\programs\python\python36\lib\site-packages\sanic_cors\extension.py", line 266, in unapplied_cors_response_middleware
    set_cors_headers(req, resp, context, res_options)
  File "c:\users\feder\appdata\local\programs\python\python36\lib\site-packages\sanic_cors\core.py", line 248, in set_cors_headers
    if resp.headers is None:
AttributeError: 'list' object has no attribute 'headers'
2019-06-24 23:54:23,267 [ERROR]  Exception occurred in one of response middleware handlers
Traceback (most recent call last):
  File "c:\users\feder\appdata\local\programs\python\python36\lib\site-packages\sanic\app.py", line 958, in handle_request
    request, response
  File "c:\users\feder\appdata\local\programs\python\python36\lib\site-packages\spf\framework.py", line 543, in _run_response_middleware
    _response = await _response
  File "c:\users\feder\appdata\local\programs\python\python36\lib\site-packages\sanic_cors\extension.py", line 266, in unapplied_cors_response_middleware
    set_cors_headers(req, resp, context, res_options)
  File "c:\users\feder\appdata\local\programs\python\python36\lib\site-packages\sanic_cors\core.py", line 248, in set_cors_headers
    if resp.headers is None:
AttributeError: 'list' object has no attribute 'headers'
2019-06-24 23:55:01,370 [ERROR]  Exception occurred in one of response middleware handlers
Traceback (most recent call last):
  File "c:\users\feder\appdata\local\programs\python\python36\lib\site-packages\sanic\app.py", line 958, in handle_request
    request, response
  File "c:\users\feder\appdata\local\programs\python\python36\lib\site-packages\spf\framework.py", line 543, in _run_response_middleware
    _response = await _response
  File "c:\users\feder\appdata\local\programs\python\python36\lib\site-packages\sanic_cors\extension.py", line 266, in unapplied_cors_response_middleware
    set_cors_headers(req, resp, context, res_options)
  File "c:\users\feder\appdata\local\programs\python\python36\lib\site-packages\sanic_cors\core.py", line 248, in set_cors_headers
    if resp.headers is None:
AttributeError: 'list' object has no attribute 'headers'
2019-06-24 23:56:02,268 [ERROR]  Exception occurred while handling uri: unknown
NoneType: None
2019-06-24 23:57:08,904 [ERROR]  Exception occurred in one of response middleware handlers
Traceback (most recent call last):
  File "c:\users\feder\appdata\local\programs\python\python36\lib\site-packages\sanic\app.py", line 958, in handle_request
    request, response
  File "c:\users\feder\appdata\local\programs\python\python36\lib\site-packages\spf\framework.py", line 543, in _run_response_middleware
    _response = await _response
  File "c:\users\feder\appdata\local\programs\python\python36\lib\site-packages\sanic_cors\extension.py", line 266, in unapplied_cors_response_middleware
    set_cors_headers(req, resp, context, res_options)
  File "c:\users\feder\appdata\local\programs\python\python36\lib\site-packages\sanic_cors\core.py", line 248, in set_cors_headers
    if resp.headers is None:
AttributeError: 'list' object has no attribute 'headers'
2019-06-24 23:58:47,610 [ERROR]  Exception occurred in one of response middleware handlers
Traceback (most recent call last):
  File "c:\users\feder\appdata\local\programs\python\python36\lib\site-packages\sanic\app.py", line 958, in handle_request
    request, response
  File "c:\users\feder\appdata\local\programs\python\python36\lib\site-packages\spf\framework.py", line 543, in _run_response_middleware
    _response = await _response
  File "c:\users\feder\appdata\local\programs\python\python36\lib\site-packages\sanic_cors\extension.py", line 266, in unapplied_cors_response_middleware
    set_cors_headers(req, resp, context, res_options)
  File "c:\users\feder\appdata\local\programs\python\python36\lib\site-packages\sanic_cors\core.py", line 248, in set_cors_headers
    if resp.headers is None:
AttributeError: 'list' object has no attribute 'headers'
2019-06-24 23:59:09,963 [ERROR]  Exception occurred in one of response middleware handlers
Traceback (most recent call last):
  File "c:\users\feder\appdata\local\programs\python\python36\lib\site-packages\sanic\app.py", line 958, in handle_request
    request, response
  File "c:\users\feder\appdata\local\programs\python\python36\lib\site-packages\spf\framework.py", line 543, in _run_response_middleware
    _response = await _response
  File "c:\users\feder\appdata\local\programs\python\python36\lib\site-packages\sanic_cors\extension.py", line 266, in unapplied_cors_response_middleware
    set_cors_headers(req, resp, context, res_options)
  File "c:\users\feder\appdata\local\programs\python\python36\lib\site-packages\sanic_cors\core.py", line 248, in set_cors_headers
    if resp.headers is None:
AttributeError: 'list' object has no attribute 'headers'
2019-06-24 23:59:27,935 [ERROR]  Exception occurred in one of response middleware handlers
Traceback (most recent call last):
  File "c:\users\feder\appdata\local\programs\python\python36\lib\site-packages\sanic\app.py", line 958, in handle_request
    request, response
  File "c:\users\feder\appdata\local\programs\python\python36\lib\site-packages\spf\framework.py", line 543, in _run_response_middleware
    _response = await _response
  File "c:\users\feder\appdata\local\programs\python\python36\lib\site-packages\sanic_cors\extension.py", line 266, in unapplied_cors_response_middleware
    set_cors_headers(req, resp, context, res_options)
  File "c:\users\feder\appdata\local\programs\python\python36\lib\site-packages\sanic_cors\core.py", line 248, in set_cors_headers
    if resp.headers is None:
AttributeError: 'list' object has no attribute 'headers'
2019-06-25 00:01:35,065 [ERROR]  Exception occurred in one of response middleware handlers
Traceback (most recent call last):
  File "c:\users\feder\appdata\local\programs\python\python36\lib\site-packages\sanic\app.py", line 958, in handle_request
    request, response
  File "c:\users\feder\appdata\local\programs\python\python36\lib\site-packages\spf\framework.py", line 543, in _run_response_middleware
    _response = await _response
  File "c:\users\feder\appdata\local\programs\python\python36\lib\site-packages\sanic_cors\extension.py", line 266, in unapplied_cors_response_middleware
    set_cors_headers(req, resp, context, res_options)
  File "c:\users\feder\appdata\local\programs\python\python36\lib\site-packages\sanic_cors\core.py", line 248, in set_cors_headers
    if resp.headers is None:
AttributeError: 'list' object has no attribute 'headers'
2019-06-25 00:02:11,027 [ERROR]  Exception occurred in one of response middleware handlers
Traceback (most recent call last):
  File "c:\users\feder\appdata\local\programs\python\python36\lib\site-packages\sanic\app.py", line 958, in handle_request
    request, response
  File "c:\users\feder\appdata\local\programs\python\python36\lib\site-packages\spf\framework.py", line 543, in _run_response_middleware
    _response = await _response
  File "c:\users\feder\appdata\local\programs\python\python36\lib\site-packages\sanic_cors\extension.py", line 266, in unapplied_cors_response_middleware
    set_cors_headers(req, resp, context, res_options)
  File "c:\users\feder\appdata\local\programs\python\python36\lib\site-packages\sanic_cors\core.py", line 248, in set_cors_headers
    if resp.headers is None:
AttributeError: 'list' object has no attribute 'headers'
2019-06-25 00:06:03,078 [ERROR]  Exception occurred in one of response middleware handlers
Traceback (most recent call last):
  File "c:\users\feder\appdata\local\programs\python\python36\lib\site-packages\sanic\app.py", line 958, in handle_request
    request, response
  File "c:\users\feder\appdata\local\programs\python\python36\lib\site-packages\spf\framework.py", line 543, in _run_response_middleware
    _response = await _response
  File "c:\users\feder\appdata\local\programs\python\python36\lib\site-packages\sanic_cors\extension.py", line 266, in unapplied_cors_response_middleware
    set_cors_headers(req, resp, context, res_options)
  File "c:\users\feder\appdata\local\programs\python\python36\lib\site-packages\sanic_cors\core.py", line 248, in set_cors_headers
    if resp.headers is None:
AttributeError: 'list' object has no attribute 'headers'
2019-06-25 00:06:23,805 [ERROR]  Exception occurred in one of response middleware handlers
Traceback (most recent call last):
  File "c:\users\feder\appdata\local\programs\python\python36\lib\site-packages\sanic\app.py", line 958, in handle_request
    request, response
  File "c:\users\feder\appdata\local\programs\python\python36\lib\site-packages\spf\framework.py", line 543, in _run_response_middleware
    _response = await _response
  File "c:\users\feder\appdata\local\programs\python\python36\lib\site-packages\sanic_cors\extension.py", line 266, in unapplied_cors_response_middleware
    set_cors_headers(req, resp, context, res_options)
  File "c:\users\feder\appdata\local\programs\python\python36\lib\site-packages\sanic_cors\core.py", line 248, in set_cors_headers
    if resp.headers is None:
AttributeError: 'list' object has no attribute 'headers'
2019-06-25 00:06:53,926 [ERROR]  Exception occurred in one of response middleware handlers
Traceback (most recent call last):
  File "c:\users\feder\appdata\local\programs\python\python36\lib\site-packages\sanic\app.py", line 958, in handle_request
    request, response
  File "c:\users\feder\appdata\local\programs\python\python36\lib\site-packages\spf\framework.py", line 543, in _run_response_middleware
    _response = await _response
  File "c:\users\feder\appdata\local\programs\python\python36\lib\site-packages\sanic_cors\extension.py", line 266, in unapplied_cors_response_middleware
    set_cors_headers(req, resp, context, res_options)
  File "c:\users\feder\appdata\local\programs\python\python36\lib\site-packages\sanic_cors\core.py", line 248, in set_cors_headers
    if resp.headers is None:
AttributeError: 'list' object has no attribute 'headers'
2019-06-25 00:07:31,559 [ERROR]  Exception occurred in one of response middleware handlers
Traceback (most recent call last):
  File "c:\users\feder\appdata\local\programs\python\python36\lib\site-packages\sanic\app.py", line 958, in handle_request
    request, response
  File "c:\users\feder\appdata\local\programs\python\python36\lib\site-packages\spf\framework.py", line 543, in _run_response_middleware
    _response = await _response
  File "c:\users\feder\appdata\local\programs\python\python36\lib\site-packages\sanic_cors\extension.py", line 266, in unapplied_cors_response_middleware
    set_cors_headers(req, resp, context, res_options)
  File "c:\users\feder\appdata\local\programs\python\python36\lib\site-packages\sanic_cors\core.py", line 248, in set_cors_headers
    if resp.headers is None:
AttributeError: 'list' object has no attribute 'headers'
2019-06-25 00:07:34,790 [ERROR]  Exception occurred in one of response middleware handlers
Traceback (most recent call last):
  File "c:\users\feder\appdata\local\programs\python\python36\lib\site-packages\sanic\app.py", line 958, in handle_request
    request, response
  File "c:\users\feder\appdata\local\programs\python\python36\lib\site-packages\spf\framework.py", line 543, in _run_response_middleware
    _response = await _response
  File "c:\users\feder\appdata\local\programs\python\python36\lib\site-packages\sanic_cors\extension.py", line 266, in unapplied_cors_response_middleware
    set_cors_headers(req, resp, context, res_options)
  File "c:\users\feder\appdata\local\programs\python\python36\lib\site-packages\sanic_cors\core.py", line 248, in set_cors_headers
    if resp.headers is None:
AttributeError: 'list' object has no attribute 'headers'
2019-06-25 00:08:16,392 [ERROR]  Exception occurred in one of response middleware handlers
Traceback (most recent call last):
  File "c:\users\feder\appdata\local\programs\python\python36\lib\site-packages\sanic\app.py", line 958, in handle_request
    request, response
  File "c:\users\feder\appdata\local\programs\python\python36\lib\site-packages\spf\framework.py", line 543, in _run_response_middleware
    _response = await _response
  File "c:\users\feder\appdata\local\programs\python\python36\lib\site-packages\sanic_cors\extension.py", line 266, in unapplied_cors_response_middleware
    set_cors_headers(req, resp, context, res_options)
  File "c:\users\feder\appdata\local\programs\python\python36\lib\site-packages\sanic_cors\core.py", line 248, in set_cors_headers
    if resp.headers is None:
AttributeError: 'list' object has no attribute 'headers'
2019-06-25 00:08:26,264 [ERROR]  Exception occurred in one of response middleware handlers
Traceback (most recent call last):
  File "c:\users\feder\appdata\local\programs\python\python36\lib\site-packages\sanic\app.py", line 958, in handle_request
    request, response
  File "c:\users\feder\appdata\local\programs\python\python36\lib\site-packages\spf\framework.py", line 543, in _run_response_middleware
    _response = await _response
  File "c:\users\feder\appdata\local\programs\python\python36\lib\site-packages\sanic_cors\extension.py", line 266, in unapplied_cors_response_middleware
    set_cors_headers(req, resp, context, res_options)
  File "c:\users\feder\appdata\local\programs\python\python36\lib\site-packages\sanic_cors\core.py", line 248, in set_cors_headers
    if resp.headers is None:
AttributeError: 'list' object has no attribute 'headers'
2019-06-25 00:24:47,526 [ERROR]  Exception occurred in one of response middleware handlers
Traceback (most recent call last):
  File "c:\users\feder\appdata\local\programs\python\python36\lib\site-packages\sanic\app.py", line 958, in handle_request
    request, response
  File "c:\users\feder\appdata\local\programs\python\python36\lib\site-packages\spf\framework.py", line 543, in _run_response_middleware
    _response = await _response
  File "c:\users\feder\appdata\local\programs\python\python36\lib\site-packages\sanic_cors\extension.py", line 266, in unapplied_cors_response_middleware
    set_cors_headers(req, resp, context, res_options)
  File "c:\users\feder\appdata\local\programs\python\python36\lib\site-packages\sanic_cors\core.py", line 248, in set_cors_headers
    if resp.headers is None:
AttributeError: 'list' object has no attribute 'headers'
2019-06-25 00:48:49,189 [ERROR]  Exception occurred in one of response middleware handlers
Traceback (most recent call last):
  File "c:\users\feder\appdata\local\programs\python\python36\lib\site-packages\sanic\app.py", line 958, in handle_request
    request, response
  File "c:\users\feder\appdata\local\programs\python\python36\lib\site-packages\spf\framework.py", line 543, in _run_response_middleware
    _response = await _response
  File "c:\users\feder\appdata\local\programs\python\python36\lib\site-packages\sanic_cors\extension.py", line 266, in unapplied_cors_response_middleware
    set_cors_headers(req, resp, context, res_options)
  File "c:\users\feder\appdata\local\programs\python\python36\lib\site-packages\sanic_cors\core.py", line 248, in set_cors_headers
    if resp.headers is None:
AttributeError: 'list' object has no attribute 'headers'
2019-06-25 00:49:05,350 [ERROR]  Exception occurred in one of response middleware handlers
Traceback (most recent call last):
  File "c:\users\feder\appdata\local\programs\python\python36\lib\site-packages\sanic\app.py", line 958, in handle_request
    request, response
  File "c:\users\feder\appdata\local\programs\python\python36\lib\site-packages\spf\framework.py", line 543, in _run_response_middleware
    _response = await _response
  File "c:\users\feder\appdata\local\programs\python\python36\lib\site-packages\sanic_cors\extension.py", line 266, in unapplied_cors_response_middleware
    set_cors_headers(req, resp, context, res_options)
  File "c:\users\feder\appdata\local\programs\python\python36\lib\site-packages\sanic_cors\core.py", line 248, in set_cors_headers
    if resp.headers is None:
AttributeError: 'list' object has no attribute 'headers'
2019-06-25 00:49:42,887 [ERROR]  Exception occurred in one of response middleware handlers
Traceback (most recent call last):
  File "c:\users\feder\appdata\local\programs\python\python36\lib\site-packages\sanic\app.py", line 958, in handle_request
    request, response
  File "c:\users\feder\appdata\local\programs\python\python36\lib\site-packages\spf\framework.py", line 543, in _run_response_middleware
    _response = await _response
  File "c:\users\feder\appdata\local\programs\python\python36\lib\site-packages\sanic_cors\extension.py", line 266, in unapplied_cors_response_middleware
    set_cors_headers(req, resp, context, res_options)
  File "c:\users\feder\appdata\local\programs\python\python36\lib\site-packages\sanic_cors\core.py", line 248, in set_cors_headers
    if resp.headers is None:
AttributeError: 'list' object has no attribute 'headers'
2019-06-25 00:49:54,613 [ERROR]  Exception occurred in one of response middleware handlers
Traceback (most recent call last):
  File "c:\users\feder\appdata\local\programs\python\python36\lib\site-packages\sanic\app.py", line 958, in handle_request
    request, response
  File "c:\users\feder\appdata\local\programs\python\python36\lib\site-packages\spf\framework.py", line 543, in _run_response_middleware
    _response = await _response
  File "c:\users\feder\appdata\local\programs\python\python36\lib\site-packages\sanic_cors\extension.py", line 266, in unapplied_cors_response_middleware
    set_cors_headers(req, resp, context, res_options)
  File "c:\users\feder\appdata\local\programs\python\python36\lib\site-packages\sanic_cors\core.py", line 248, in set_cors_headers
    if resp.headers is None:
AttributeError: 'list' object has no attribute 'headers'
2019-06-25 01:03:29,641 [ERROR]  Exception occurred in one of response middleware handlers
Traceback (most recent call last):
  File "c:\users\feder\appdata\local\programs\python\python36\lib\site-packages\sanic\app.py", line 958, in handle_request
    request, response
  File "c:\users\feder\appdata\local\programs\python\python36\lib\site-packages\spf\framework.py", line 543, in _run_response_middleware
    _response = await _response
  File "c:\users\feder\appdata\local\programs\python\python36\lib\site-packages\sanic_cors\extension.py", line 266, in unapplied_cors_response_middleware
    set_cors_headers(req, resp, context, res_options)
  File "c:\users\feder\appdata\local\programs\python\python36\lib\site-packages\sanic_cors\core.py", line 248, in set_cors_headers
    if resp.headers is None:
AttributeError: 'list' object has no attribute 'headers'
2019-06-25 01:03:47,635 [ERROR]  Exception occurred in one of response middleware handlers
Traceback (most recent call last):
  File "c:\users\feder\appdata\local\programs\python\python36\lib\site-packages\sanic\app.py", line 958, in handle_request
    request, response
  File "c:\users\feder\appdata\local\programs\python\python36\lib\site-packages\spf\framework.py", line 543, in _run_response_middleware
    _response = await _response
  File "c:\users\feder\appdata\local\programs\python\python36\lib\site-packages\sanic_cors\extension.py", line 266, in unapplied_cors_response_middleware
    set_cors_headers(req, resp, context, res_options)
  File "c:\users\feder\appdata\local\programs\python\python36\lib\site-packages\sanic_cors\core.py", line 248, in set_cors_headers
    if resp.headers is None:
AttributeError: 'list' object has no attribute 'headers'
2019-06-25 01:04:14,269 [ERROR]  Exception occurred in one of response middleware handlers
Traceback (most recent call last):
  File "c:\users\feder\appdata\local\programs\python\python36\lib\site-packages\sanic\app.py", line 958, in handle_request
    request, response
  File "c:\users\feder\appdata\local\programs\python\python36\lib\site-packages\spf\framework.py", line 543, in _run_response_middleware
    _response = await _response
  File "c:\users\feder\appdata\local\programs\python\python36\lib\site-packages\sanic_cors\extension.py", line 266, in unapplied_cors_response_middleware
    set_cors_headers(req, resp, context, res_options)
  File "c:\users\feder\appdata\local\programs\python\python36\lib\site-packages\sanic_cors\core.py", line 248, in set_cors_headers
    if resp.headers is None:
AttributeError: 'list' object has no attribute 'headers'
2019-06-25 01:04:28,520 [ERROR]  Exception occurred in one of response middleware handlers
Traceback (most recent call last):
  File "c:\users\feder\appdata\local\programs\python\python36\lib\site-packages\sanic\app.py", line 958, in handle_request
    request, response
  File "c:\users\feder\appdata\local\programs\python\python36\lib\site-packages\spf\framework.py", line 543, in _run_response_middleware
    _response = await _response
  File "c:\users\feder\appdata\local\programs\python\python36\lib\site-packages\sanic_cors\extension.py", line 266, in unapplied_cors_response_middleware
    set_cors_headers(req, resp, context, res_options)
  File "c:\users\feder\appdata\local\programs\python\python36\lib\site-packages\sanic_cors\core.py", line 248, in set_cors_headers
    if resp.headers is None:
AttributeError: 'list' object has no attribute 'headers'
2019-06-25 01:04:40,571 [ERROR]  Exception occurred in one of response middleware handlers
Traceback (most recent call last):
  File "c:\users\feder\appdata\local\programs\python\python36\lib\site-packages\sanic\app.py", line 958, in handle_request
    request, response
  File "c:\users\feder\appdata\local\programs\python\python36\lib\site-packages\spf\framework.py", line 543, in _run_response_middleware
    _response = await _response
  File "c:\users\feder\appdata\local\programs\python\python36\lib\site-packages\sanic_cors\extension.py", line 266, in unapplied_cors_response_middleware
    set_cors_headers(req, resp, context, res_options)
  File "c:\users\feder\appdata\local\programs\python\python36\lib\site-packages\sanic_cors\core.py", line 248, in set_cors_headers
    if resp.headers is None:
AttributeError: 'list' object has no attribute 'headers'
2019-06-25 01:05:59,065 [ERROR]  Exception occurred in one of response middleware handlers
Traceback (most recent call last):
  File "c:\users\feder\appdata\local\programs\python\python36\lib\site-packages\sanic\app.py", line 958, in handle_request
    request, response
  File "c:\users\feder\appdata\local\programs\python\python36\lib\site-packages\spf\framework.py", line 543, in _run_response_middleware
    _response = await _response
  File "c:\users\feder\appdata\local\programs\python\python36\lib\site-packages\sanic_cors\extension.py", line 266, in unapplied_cors_response_middleware
    set_cors_headers(req, resp, context, res_options)
  File "c:\users\feder\appdata\local\programs\python\python36\lib\site-packages\sanic_cors\core.py", line 248, in set_cors_headers
    if resp.headers is None:
AttributeError: 'list' object has no attribute 'headers'
2019-06-25 01:06:08,197 [ERROR]  Exception occurred in one of response middleware handlers
Traceback (most recent call last):
  File "c:\users\feder\appdata\local\programs\python\python36\lib\site-packages\sanic\app.py", line 958, in handle_request
    request, response
  File "c:\users\feder\appdata\local\programs\python\python36\lib\site-packages\spf\framework.py", line 543, in _run_response_middleware
    _response = await _response
  File "c:\users\feder\appdata\local\programs\python\python36\lib\site-packages\sanic_cors\extension.py", line 266, in unapplied_cors_response_middleware
    set_cors_headers(req, resp, context, res_options)
  File "c:\users\feder\appdata\local\programs\python\python36\lib\site-packages\sanic_cors\core.py", line 248, in set_cors_headers
    if resp.headers is None:
AttributeError: 'list' object has no attribute 'headers'
2019-06-25 01:08:47,858 [ERROR]  Exception occurred in one of response middleware handlers
Traceback (most recent call last):
  File "c:\users\feder\appdata\local\programs\python\python36\lib\site-packages\sanic\app.py", line 958, in handle_request
    request, response
  File "c:\users\feder\appdata\local\programs\python\python36\lib\site-packages\spf\framework.py", line 543, in _run_response_middleware
    _response = await _response
  File "c:\users\feder\appdata\local\programs\python\python36\lib\site-packages\sanic_cors\extension.py", line 266, in unapplied_cors_response_middleware
    set_cors_headers(req, resp, context, res_options)
  File "c:\users\feder\appdata\local\programs\python\python36\lib\site-packages\sanic_cors\core.py", line 248, in set_cors_headers
    if resp.headers is None:
AttributeError: 'list' object has no attribute 'headers'
2019-06-25 01:24:42,162 [ERROR]  Exception occurred in one of response middleware handlers
Traceback (most recent call last):
  File "c:\users\feder\appdata\local\programs\python\python36\lib\site-packages\sanic\app.py", line 958, in handle_request
    request, response
  File "c:\users\feder\appdata\local\programs\python\python36\lib\site-packages\spf\framework.py", line 543, in _run_response_middleware
    _response = await _response
  File "c:\users\feder\appdata\local\programs\python\python36\lib\site-packages\sanic_cors\extension.py", line 266, in unapplied_cors_response_middleware
    set_cors_headers(req, resp, context, res_options)
  File "c:\users\feder\appdata\local\programs\python\python36\lib\site-packages\sanic_cors\core.py", line 248, in set_cors_headers
    if resp.headers is None:
AttributeError: 'list' object has no attribute 'headers'
2019-06-25 01:25:32,190 [ERROR]  Exception occurred in one of response middleware handlers
Traceback (most recent call last):
  File "c:\users\feder\appdata\local\programs\python\python36\lib\site-packages\sanic\app.py", line 958, in handle_request
    request, response
  File "c:\users\feder\appdata\local\programs\python\python36\lib\site-packages\spf\framework.py", line 543, in _run_response_middleware
    _response = await _response
  File "c:\users\feder\appdata\local\programs\python\python36\lib\site-packages\sanic_cors\extension.py", line 266, in unapplied_cors_response_middleware
    set_cors_headers(req, resp, context, res_options)
  File "c:\users\feder\appdata\local\programs\python\python36\lib\site-packages\sanic_cors\core.py", line 248, in set_cors_headers
    if resp.headers is None:
AttributeError: 'list' object has no attribute 'headers'
2019-06-25 01:25:47,898 [ERROR]  Exception occurred in one of response middleware handlers
Traceback (most recent call last):
  File "c:\users\feder\appdata\local\programs\python\python36\lib\site-packages\sanic\app.py", line 958, in handle_request
    request, response
  File "c:\users\feder\appdata\local\programs\python\python36\lib\site-packages\spf\framework.py", line 543, in _run_response_middleware
    _response = await _response
  File "c:\users\feder\appdata\local\programs\python\python36\lib\site-packages\sanic_cors\extension.py", line 266, in unapplied_cors_response_middleware
    set_cors_headers(req, resp, context, res_options)
  File "c:\users\feder\appdata\local\programs\python\python36\lib\site-packages\sanic_cors\core.py", line 248, in set_cors_headers
    if resp.headers is None:
AttributeError: 'list' object has no attribute 'headers'
2019-06-25 01:26:21,573 [ERROR]  Exception occurred in one of response middleware handlers
Traceback (most recent call last):
  File "c:\users\feder\appdata\local\programs\python\python36\lib\site-packages\sanic\app.py", line 958, in handle_request
    request, response
  File "c:\users\feder\appdata\local\programs\python\python36\lib\site-packages\spf\framework.py", line 543, in _run_response_middleware
    _response = await _response
  File "c:\users\feder\appdata\local\programs\python\python36\lib\site-packages\sanic_cors\extension.py", line 266, in unapplied_cors_response_middleware
    set_cors_headers(req, resp, context, res_options)
  File "c:\users\feder\appdata\local\programs\python\python36\lib\site-packages\sanic_cors\core.py", line 248, in set_cors_headers
    if resp.headers is None:
AttributeError: 'list' object has no attribute 'headers'
2019-06-25 01:27:22,362 [ERROR]  Exception occurred while handling uri: unknown
NoneType: None
2019-06-25 01:27:24,165 [ERROR]  Exception occurred in one of response middleware handlers
Traceback (most recent call last):
  File "c:\users\feder\appdata\local\programs\python\python36\lib\site-packages\sanic\app.py", line 958, in handle_request
    request, response
  File "c:\users\feder\appdata\local\programs\python\python36\lib\site-packages\spf\framework.py", line 543, in _run_response_middleware
    _response = await _response
  File "c:\users\feder\appdata\local\programs\python\python36\lib\site-packages\sanic_cors\extension.py", line 266, in unapplied_cors_response_middleware
    set_cors_headers(req, resp, context, res_options)
  File "c:\users\feder\appdata\local\programs\python\python36\lib\site-packages\sanic_cors\core.py", line 248, in set_cors_headers
    if resp.headers is None:
AttributeError: 'list' object has no attribute 'headers'
2019-06-25 01:28:10,731 [ERROR]  Exception occurred in one of response middleware handlers
Traceback (most recent call last):
  File "c:\users\feder\appdata\local\programs\python\python36\lib\site-packages\sanic\app.py", line 958, in handle_request
    request, response
  File "c:\users\feder\appdata\local\programs\python\python36\lib\site-packages\spf\framework.py", line 543, in _run_response_middleware
    _response = await _response
  File "c:\users\feder\appdata\local\programs\python\python36\lib\site-packages\sanic_cors\extension.py", line 266, in unapplied_cors_response_middleware
    set_cors_headers(req, resp, context, res_options)
  File "c:\users\feder\appdata\local\programs\python\python36\lib\site-packages\sanic_cors\core.py", line 248, in set_cors_headers
    if resp.headers is None:
AttributeError: 'list' object has no attribute 'headers'
2019-06-25 01:29:11,518 [ERROR]  Exception occurred while handling uri: unknown
NoneType: None
2019-06-25 01:42:49,826 [ERROR]  Exception occurred in one of response middleware handlers
Traceback (most recent call last):
  File "c:\users\feder\appdata\local\programs\python\python36\lib\site-packages\sanic\app.py", line 958, in handle_request
    request, response
  File "c:\users\feder\appdata\local\programs\python\python36\lib\site-packages\spf\framework.py", line 543, in _run_response_middleware
    _response = await _response
  File "c:\users\feder\appdata\local\programs\python\python36\lib\site-packages\sanic_cors\extension.py", line 266, in unapplied_cors_response_middleware
    set_cors_headers(req, resp, context, res_options)
  File "c:\users\feder\appdata\local\programs\python\python36\lib\site-packages\sanic_cors\core.py", line 248, in set_cors_headers
    if resp.headers is None:
AttributeError: 'list' object has no attribute 'headers'
2019-06-25 01:45:30,398 [ERROR]  Exception occurred in one of response middleware handlers
Traceback (most recent call last):
  File "c:\users\feder\appdata\local\programs\python\python36\lib\site-packages\sanic\app.py", line 958, in handle_request
    request, response
  File "c:\users\feder\appdata\local\programs\python\python36\lib\site-packages\spf\framework.py", line 543, in _run_response_middleware
    _response = await _response
  File "c:\users\feder\appdata\local\programs\python\python36\lib\site-packages\sanic_cors\extension.py", line 266, in unapplied_cors_response_middleware
    set_cors_headers(req, resp, context, res_options)
  File "c:\users\feder\appdata\local\programs\python\python36\lib\site-packages\sanic_cors\core.py", line 248, in set_cors_headers
    if resp.headers is None:
AttributeError: 'list' object has no attribute 'headers'
2019-06-25 01:45:37,928 [ERROR]  Exception occurred in one of response middleware handlers
Traceback (most recent call last):
  File "c:\users\feder\appdata\local\programs\python\python36\lib\site-packages\sanic\app.py", line 958, in handle_request
    request, response
  File "c:\users\feder\appdata\local\programs\python\python36\lib\site-packages\spf\framework.py", line 543, in _run_response_middleware
    _response = await _response
  File "c:\users\feder\appdata\local\programs\python\python36\lib\site-packages\sanic_cors\extension.py", line 266, in unapplied_cors_response_middleware
    set_cors_headers(req, resp, context, res_options)
  File "c:\users\feder\appdata\local\programs\python\python36\lib\site-packages\sanic_cors\core.py", line 248, in set_cors_headers
    if resp.headers is None:
AttributeError: 'list' object has no attribute 'headers'
2019-06-25 01:48:49,955 [ERROR]  Exception occurred in one of response middleware handlers
Traceback (most recent call last):
  File "c:\users\feder\appdata\local\programs\python\python36\lib\site-packages\sanic\app.py", line 958, in handle_request
    request, response
  File "c:\users\feder\appdata\local\programs\python\python36\lib\site-packages\spf\framework.py", line 543, in _run_response_middleware
    _response = await _response
  File "c:\users\feder\appdata\local\programs\python\python36\lib\site-packages\sanic_cors\extension.py", line 266, in unapplied_cors_response_middleware
    set_cors_headers(req, resp, context, res_options)
  File "c:\users\feder\appdata\local\programs\python\python36\lib\site-packages\sanic_cors\core.py", line 248, in set_cors_headers
    if resp.headers is None:
AttributeError: 'list' object has no attribute 'headers'
2019-06-25 01:49:50,311 [ERROR]  Exception occurred in one of response middleware handlers
Traceback (most recent call last):
  File "c:\users\feder\appdata\local\programs\python\python36\lib\site-packages\sanic\app.py", line 958, in handle_request
    request, response
  File "c:\users\feder\appdata\local\programs\python\python36\lib\site-packages\spf\framework.py", line 543, in _run_response_middleware
    _response = await _response
  File "c:\users\feder\appdata\local\programs\python\python36\lib\site-packages\sanic_cors\extension.py", line 266, in unapplied_cors_response_middleware
    set_cors_headers(req, resp, context, res_options)
  File "c:\users\feder\appdata\local\programs\python\python36\lib\site-packages\sanic_cors\core.py", line 248, in set_cors_headers
    if resp.headers is None:
AttributeError: 'list' object has no attribute 'headers'
2019-06-25 01:50:08,477 [ERROR]  Exception occurred in one of response middleware handlers
Traceback (most recent call last):
  File "c:\users\feder\appdata\local\programs\python\python36\lib\site-packages\sanic\app.py", line 958, in handle_request
    request, response
  File "c:\users\feder\appdata\local\programs\python\python36\lib\site-packages\spf\framework.py", line 543, in _run_response_middleware
    _response = await _response
  File "c:\users\feder\appdata\local\programs\python\python36\lib\site-packages\sanic_cors\extension.py", line 266, in unapplied_cors_response_middleware
    set_cors_headers(req, resp, context, res_options)
  File "c:\users\feder\appdata\local\programs\python\python36\lib\site-packages\sanic_cors\core.py", line 248, in set_cors_headers
    if resp.headers is None:
AttributeError: 'list' object has no attribute 'headers'
2019-06-25 01:50:28,701 [ERROR]  Exception occurred in one of response middleware handlers
Traceback (most recent call last):
  File "c:\users\feder\appdata\local\programs\python\python36\lib\site-packages\sanic\app.py", line 958, in handle_request
    request, response
  File "c:\users\feder\appdata\local\programs\python\python36\lib\site-packages\spf\framework.py", line 543, in _run_response_middleware
    _response = await _response
  File "c:\users\feder\appdata\local\programs\python\python36\lib\site-packages\sanic_cors\extension.py", line 266, in unapplied_cors_response_middleware
    set_cors_headers(req, resp, context, res_options)
  File "c:\users\feder\appdata\local\programs\python\python36\lib\site-packages\sanic_cors\core.py", line 248, in set_cors_headers
    if resp.headers is None:
AttributeError: 'list' object has no attribute 'headers'
2019-06-25 01:51:24,532 [ERROR]  Exception occurred in one of response middleware handlers
Traceback (most recent call last):
  File "c:\users\feder\appdata\local\programs\python\python36\lib\site-packages\sanic\app.py", line 958, in handle_request
    request, response
  File "c:\users\feder\appdata\local\programs\python\python36\lib\site-packages\spf\framework.py", line 543, in _run_response_middleware
    _response = await _response
  File "c:\users\feder\appdata\local\programs\python\python36\lib\site-packages\sanic_cors\extension.py", line 266, in unapplied_cors_response_middleware
    set_cors_headers(req, resp, context, res_options)
  File "c:\users\feder\appdata\local\programs\python\python36\lib\site-packages\sanic_cors\core.py", line 248, in set_cors_headers
    if resp.headers is None:
AttributeError: 'list' object has no attribute 'headers'
2019-06-25 01:51:26,049 [ERROR]  Exception occurred in one of response middleware handlers
Traceback (most recent call last):
  File "c:\users\feder\appdata\local\programs\python\python36\lib\site-packages\sanic\app.py", line 958, in handle_request
    request, response
  File "c:\users\feder\appdata\local\programs\python\python36\lib\site-packages\spf\framework.py", line 543, in _run_response_middleware
    _response = await _response
  File "c:\users\feder\appdata\local\programs\python\python36\lib\site-packages\sanic_cors\extension.py", line 266, in unapplied_cors_response_middleware
    set_cors_headers(req, resp, context, res_options)
  File "c:\users\feder\appdata\local\programs\python\python36\lib\site-packages\sanic_cors\core.py", line 248, in set_cors_headers
    if resp.headers is None:
AttributeError: 'list' object has no attribute 'headers'
2019-06-25 01:51:34,229 [ERROR]  Exception occurred in one of response middleware handlers
Traceback (most recent call last):
  File "c:\users\feder\appdata\local\programs\python\python36\lib\site-packages\sanic\app.py", line 958, in handle_request
    request, response
  File "c:\users\feder\appdata\local\programs\python\python36\lib\site-packages\spf\framework.py", line 543, in _run_response_middleware
    _response = await _response
  File "c:\users\feder\appdata\local\programs\python\python36\lib\site-packages\sanic_cors\extension.py", line 266, in unapplied_cors_response_middleware
    set_cors_headers(req, resp, context, res_options)
  File "c:\users\feder\appdata\local\programs\python\python36\lib\site-packages\sanic_cors\core.py", line 248, in set_cors_headers
    if resp.headers is None:
AttributeError: 'list' object has no attribute 'headers'
2019-06-25 01:51:49,361 [ERROR]  Exception occurred in one of response middleware handlers
Traceback (most recent call last):
  File "c:\users\feder\appdata\local\programs\python\python36\lib\site-packages\sanic\app.py", line 958, in handle_request
    request, response
  File "c:\users\feder\appdata\local\programs\python\python36\lib\site-packages\spf\framework.py", line 543, in _run_response_middleware
    _response = await _response
  File "c:\users\feder\appdata\local\programs\python\python36\lib\site-packages\sanic_cors\extension.py", line 266, in unapplied_cors_response_middleware
    set_cors_headers(req, resp, context, res_options)
  File "c:\users\feder\appdata\local\programs\python\python36\lib\site-packages\sanic_cors\core.py", line 248, in set_cors_headers
    if resp.headers is None:
AttributeError: 'list' object has no attribute 'headers'
2019-06-25 01:52:34,905 [ERROR]  Exception occurred in one of response middleware handlers
Traceback (most recent call last):
  File "c:\users\feder\appdata\local\programs\python\python36\lib\site-packages\sanic\app.py", line 958, in handle_request
    request, response
  File "c:\users\feder\appdata\local\programs\python\python36\lib\site-packages\spf\framework.py", line 543, in _run_response_middleware
    _response = await _response
  File "c:\users\feder\appdata\local\programs\python\python36\lib\site-packages\sanic_cors\extension.py", line 266, in unapplied_cors_response_middleware
    set_cors_headers(req, resp, context, res_options)
  File "c:\users\feder\appdata\local\programs\python\python36\lib\site-packages\sanic_cors\core.py", line 248, in set_cors_headers
    if resp.headers is None:
AttributeError: 'list' object has no attribute 'headers'
2019-06-25 01:53:32,807 [ERROR]  Exception occurred in one of response middleware handlers
Traceback (most recent call last):
  File "c:\users\feder\appdata\local\programs\python\python36\lib\site-packages\sanic\app.py", line 958, in handle_request
    request, response
  File "c:\users\feder\appdata\local\programs\python\python36\lib\site-packages\spf\framework.py", line 543, in _run_response_middleware
    _response = await _response
  File "c:\users\feder\appdata\local\programs\python\python36\lib\site-packages\sanic_cors\extension.py", line 266, in unapplied_cors_response_middleware
    set_cors_headers(req, resp, context, res_options)
  File "c:\users\feder\appdata\local\programs\python\python36\lib\site-packages\sanic_cors\core.py", line 248, in set_cors_headers
    if resp.headers is None:
AttributeError: 'list' object has no attribute 'headers'
2019-06-25 01:55:30,504 [ERROR]  Exception occurred in one of response middleware handlers
Traceback (most recent call last):
  File "c:\users\feder\appdata\local\programs\python\python36\lib\site-packages\sanic\app.py", line 958, in handle_request
    request, response
  File "c:\users\feder\appdata\local\programs\python\python36\lib\site-packages\spf\framework.py", line 543, in _run_response_middleware
    _response = await _response
  File "c:\users\feder\appdata\local\programs\python\python36\lib\site-packages\sanic_cors\extension.py", line 266, in unapplied_cors_response_middleware
    set_cors_headers(req, resp, context, res_options)
  File "c:\users\feder\appdata\local\programs\python\python36\lib\site-packages\sanic_cors\core.py", line 248, in set_cors_headers
    if resp.headers is None:
AttributeError: 'list' object has no attribute 'headers'
2019-06-25 01:55:52,125 [ERROR]  Exception occurred in one of response middleware handlers
Traceback (most recent call last):
  File "c:\users\feder\appdata\local\programs\python\python36\lib\site-packages\sanic\app.py", line 958, in handle_request
    request, response
  File "c:\users\feder\appdata\local\programs\python\python36\lib\site-packages\spf\framework.py", line 543, in _run_response_middleware
    _response = await _response
  File "c:\users\feder\appdata\local\programs\python\python36\lib\site-packages\sanic_cors\extension.py", line 266, in unapplied_cors_response_middleware
    set_cors_headers(req, resp, context, res_options)
  File "c:\users\feder\appdata\local\programs\python\python36\lib\site-packages\sanic_cors\core.py", line 248, in set_cors_headers
    if resp.headers is None:
AttributeError: 'list' object has no attribute 'headers'
2019-06-25 01:56:06,834 [ERROR]  Exception occurred in one of response middleware handlers
Traceback (most recent call last):
  File "c:\users\feder\appdata\local\programs\python\python36\lib\site-packages\sanic\app.py", line 958, in handle_request
    request, response
  File "c:\users\feder\appdata\local\programs\python\python36\lib\site-packages\spf\framework.py", line 543, in _run_response_middleware
    _response = await _response
  File "c:\users\feder\appdata\local\programs\python\python36\lib\site-packages\sanic_cors\extension.py", line 266, in unapplied_cors_response_middleware
    set_cors_headers(req, resp, context, res_options)
  File "c:\users\feder\appdata\local\programs\python\python36\lib\site-packages\sanic_cors\core.py", line 248, in set_cors_headers
    if resp.headers is None:
AttributeError: 'list' object has no attribute 'headers'
2019-06-25 01:56:43,559 [ERROR]  Exception occurred in one of response middleware handlers
Traceback (most recent call last):
  File "c:\users\feder\appdata\local\programs\python\python36\lib\site-packages\sanic\app.py", line 958, in handle_request
    request, response
  File "c:\users\feder\appdata\local\programs\python\python36\lib\site-packages\spf\framework.py", line 543, in _run_response_middleware
    _response = await _response
  File "c:\users\feder\appdata\local\programs\python\python36\lib\site-packages\sanic_cors\extension.py", line 266, in unapplied_cors_response_middleware
    set_cors_headers(req, resp, context, res_options)
  File "c:\users\feder\appdata\local\programs\python\python36\lib\site-packages\sanic_cors\core.py", line 248, in set_cors_headers
    if resp.headers is None:
AttributeError: 'list' object has no attribute 'headers'
2019-06-25 01:57:19,823 [ERROR]  Exception occurred in one of response middleware handlers
Traceback (most recent call last):
  File "c:\users\feder\appdata\local\programs\python\python36\lib\site-packages\sanic\app.py", line 958, in handle_request
    request, response
  File "c:\users\feder\appdata\local\programs\python\python36\lib\site-packages\spf\framework.py", line 543, in _run_response_middleware
    _response = await _response
  File "c:\users\feder\appdata\local\programs\python\python36\lib\site-packages\sanic_cors\extension.py", line 266, in unapplied_cors_response_middleware
    set_cors_headers(req, resp, context, res_options)
  File "c:\users\feder\appdata\local\programs\python\python36\lib\site-packages\sanic_cors\core.py", line 248, in set_cors_headers
    if resp.headers is None:
AttributeError: 'list' object has no attribute 'headers'
2019-06-25 01:59:19,204 [ERROR]  Exception occurred in one of response middleware handlers
Traceback (most recent call last):
  File "c:\users\feder\appdata\local\programs\python\python36\lib\site-packages\sanic\app.py", line 958, in handle_request
    request, response
  File "c:\users\feder\appdata\local\programs\python\python36\lib\site-packages\spf\framework.py", line 543, in _run_response_middleware
    _response = await _response
  File "c:\users\feder\appdata\local\programs\python\python36\lib\site-packages\sanic_cors\extension.py", line 266, in unapplied_cors_response_middleware
    set_cors_headers(req, resp, context, res_options)
  File "c:\users\feder\appdata\local\programs\python\python36\lib\site-packages\sanic_cors\core.py", line 248, in set_cors_headers
    if resp.headers is None:
AttributeError: 'list' object has no attribute 'headers'
2019-06-25 01:59:27,185 [ERROR]  Exception occurred in one of response middleware handlers
Traceback (most recent call last):
  File "c:\users\feder\appdata\local\programs\python\python36\lib\site-packages\sanic\app.py", line 958, in handle_request
    request, response
  File "c:\users\feder\appdata\local\programs\python\python36\lib\site-packages\spf\framework.py", line 543, in _run_response_middleware
    _response = await _response
  File "c:\users\feder\appdata\local\programs\python\python36\lib\site-packages\sanic_cors\extension.py", line 266, in unapplied_cors_response_middleware
    set_cors_headers(req, resp, context, res_options)
  File "c:\users\feder\appdata\local\programs\python\python36\lib\site-packages\sanic_cors\core.py", line 248, in set_cors_headers
    if resp.headers is None:
AttributeError: 'list' object has no attribute 'headers'
2019-06-25 01:59:39,528 [ERROR]  Exception occurred in one of response middleware handlers
Traceback (most recent call last):
  File "c:\users\feder\appdata\local\programs\python\python36\lib\site-packages\sanic\app.py", line 958, in handle_request
    request, response
  File "c:\users\feder\appdata\local\programs\python\python36\lib\site-packages\spf\framework.py", line 543, in _run_response_middleware
    _response = await _response
  File "c:\users\feder\appdata\local\programs\python\python36\lib\site-packages\sanic_cors\extension.py", line 266, in unapplied_cors_response_middleware
    set_cors_headers(req, resp, context, res_options)
  File "c:\users\feder\appdata\local\programs\python\python36\lib\site-packages\sanic_cors\core.py", line 248, in set_cors_headers
    if resp.headers is None:
AttributeError: 'list' object has no attribute 'headers'
2019-06-25 02:00:20,084 [ERROR]  Exception occurred in one of response middleware handlers
Traceback (most recent call last):
  File "c:\users\feder\appdata\local\programs\python\python36\lib\site-packages\sanic\app.py", line 958, in handle_request
    request, response
  File "c:\users\feder\appdata\local\programs\python\python36\lib\site-packages\spf\framework.py", line 543, in _run_response_middleware
    _response = await _response
  File "c:\users\feder\appdata\local\programs\python\python36\lib\site-packages\sanic_cors\extension.py", line 266, in unapplied_cors_response_middleware
    set_cors_headers(req, resp, context, res_options)
  File "c:\users\feder\appdata\local\programs\python\python36\lib\site-packages\sanic_cors\core.py", line 248, in set_cors_headers
    if resp.headers is None:
AttributeError: 'list' object has no attribute 'headers'
2019-06-25 19:32:24,023 [ERROR]  Exception occurred in one of response middleware handlers
Traceback (most recent call last):
  File "c:\users\feder\appdata\local\programs\python\python36\lib\site-packages\sanic\app.py", line 958, in handle_request
    request, response
  File "c:\users\feder\appdata\local\programs\python\python36\lib\site-packages\spf\framework.py", line 543, in _run_response_middleware
    _response = await _response
  File "c:\users\feder\appdata\local\programs\python\python36\lib\site-packages\sanic_cors\extension.py", line 266, in unapplied_cors_response_middleware
    set_cors_headers(req, resp, context, res_options)
  File "c:\users\feder\appdata\local\programs\python\python36\lib\site-packages\sanic_cors\core.py", line 248, in set_cors_headers
    if resp.headers is None:
AttributeError: 'list' object has no attribute 'headers'
2019-06-25 19:32:49,689 [ERROR]  Experienced exception while trying to serve
Traceback (most recent call last):
  File "c:\users\feder\appdata\local\programs\python\python36\lib\site-packages\sanic\app.py", line 1096, in run
    serve(**server_settings)
  File "c:\users\feder\appdata\local\programs\python\python36\lib\site-packages\sanic\server.py", line 770, in serve
    loop.run_forever()
  File "c:\users\feder\appdata\local\programs\python\python36\lib\asyncio\base_events.py", line 421, in run_forever
    self._run_once()
  File "c:\users\feder\appdata\local\programs\python\python36\lib\asyncio\base_events.py", line 1389, in _run_once
    event_list = self._selector.select(timeout)
  File "c:\users\feder\appdata\local\programs\python\python36\lib\selectors.py", line 323, in select
    r, w, _ = self._select(self._readers, self._writers, [], timeout)
  File "c:\users\feder\appdata\local\programs\python\python36\lib\selectors.py", line 314, in _select
    r, w, x = select.select(r, w, w, timeout)
  File "c:\users\feder\appdata\local\programs\python\python36\lib\site-packages\engineio\client.py", line 41, in signal_handler
    return original_signal_handler(sig, frame)
KeyboardInterrupt
2019-06-25 19:33:48,976 [ERROR]  Exception occurred in one of response middleware handlers
Traceback (most recent call last):
  File "c:\users\feder\appdata\local\programs\python\python36\lib\site-packages\sanic\app.py", line 958, in handle_request
    request, response
  File "c:\users\feder\appdata\local\programs\python\python36\lib\site-packages\spf\framework.py", line 543, in _run_response_middleware
    _response = await _response
  File "c:\users\feder\appdata\local\programs\python\python36\lib\site-packages\sanic_cors\extension.py", line 266, in unapplied_cors_response_middleware
    set_cors_headers(req, resp, context, res_options)
  File "c:\users\feder\appdata\local\programs\python\python36\lib\site-packages\sanic_cors\core.py", line 248, in set_cors_headers
    if resp.headers is None:
AttributeError: 'list' object has no attribute 'headers'
2019-06-25 19:34:35,828 [ERROR]  Exception occurred in one of response middleware handlers
Traceback (most recent call last):
  File "c:\users\feder\appdata\local\programs\python\python36\lib\site-packages\sanic\app.py", line 958, in handle_request
    request, response
  File "c:\users\feder\appdata\local\programs\python\python36\lib\site-packages\spf\framework.py", line 543, in _run_response_middleware
    _response = await _response
  File "c:\users\feder\appdata\local\programs\python\python36\lib\site-packages\sanic_cors\extension.py", line 266, in unapplied_cors_response_middleware
    set_cors_headers(req, resp, context, res_options)
  File "c:\users\feder\appdata\local\programs\python\python36\lib\site-packages\sanic_cors\core.py", line 248, in set_cors_headers
    if resp.headers is None:
AttributeError: 'list' object has no attribute 'headers'
2019-06-25 22:47:56,090 [ERROR]  Experienced exception while trying to serve
Traceback (most recent call last):
  File "c:\users\feder\appdata\local\programs\python\python36\lib\site-packages\sanic\app.py", line 1096, in run
    serve(**server_settings)
  File "c:\users\feder\appdata\local\programs\python\python36\lib\site-packages\sanic\server.py", line 770, in serve
    loop.run_forever()
  File "c:\users\feder\appdata\local\programs\python\python36\lib\asyncio\base_events.py", line 421, in run_forever
    self._run_once()
  File "c:\users\feder\appdata\local\programs\python\python36\lib\asyncio\base_events.py", line 1389, in _run_once
    event_list = self._selector.select(timeout)
  File "c:\users\feder\appdata\local\programs\python\python36\lib\selectors.py", line 323, in select
    r, w, _ = self._select(self._readers, self._writers, [], timeout)
  File "c:\users\feder\appdata\local\programs\python\python36\lib\selectors.py", line 314, in _select
    r, w, x = select.select(r, w, w, timeout)
  File "c:\users\feder\appdata\local\programs\python\python36\lib\site-packages\engineio\client.py", line 41, in signal_handler
    return original_signal_handler(sig, frame)
KeyboardInterrupt
2019-06-25 23:25:56,084 [ERROR]  Experienced exception while trying to serve
Traceback (most recent call last):
  File "c:\users\feder\appdata\local\programs\python\python36\lib\site-packages\sanic\app.py", line 1096, in run
    serve(**server_settings)
  File "c:\users\feder\appdata\local\programs\python\python36\lib\site-packages\sanic\server.py", line 770, in serve
    loop.run_forever()
  File "c:\users\feder\appdata\local\programs\python\python36\lib\asyncio\base_events.py", line 421, in run_forever
    self._run_once()
  File "c:\users\feder\appdata\local\programs\python\python36\lib\asyncio\base_events.py", line 1389, in _run_once
    event_list = self._selector.select(timeout)
  File "c:\users\feder\appdata\local\programs\python\python36\lib\selectors.py", line 323, in select
    r, w, _ = self._select(self._readers, self._writers, [], timeout)
  File "c:\users\feder\appdata\local\programs\python\python36\lib\selectors.py", line 314, in _select
    r, w, x = select.select(r, w, w, timeout)
  File "c:\users\feder\appdata\local\programs\python\python36\lib\site-packages\engineio\client.py", line 41, in signal_handler
    return original_signal_handler(sig, frame)
KeyboardInterrupt
